Workbook

Sheet Dashboard
B2: PLUME PARAGLIDERS
B3: Business Plan 2025-2031 • Tableau de Bord Exécutif
B6: 📊 INDICATEURS CLÉS | K6: 💼 PLAN DE FINANCEMENT
B7: 📅 CRÉATION | C7: 18 décembre 2025 | K7: JB Chandelier | L7: =Financement!B5 -> 104000 | M7: 55%
B8: Capital social | D8: Plan de financement | F8: Seuil rentabilité | H8: Marge nette/aile | K8: Thomas Pierre-Bes | L8: =Financement!B6 -> 85000 | M8: 45%
B9: =Financement!C7 -> 100000 | D9: =L12 -> 428000 | F9: =MAX('Seuil Rentabilité'!B21:D21) -> 204 | H9: =ROUND('Seuil Rentabilité'!B8,0)&" €" -> 1080 € | K9: Emprunt 4 ans | L9: ='Emprunt Bancaire'!B4 -> 189000
K10: Avoir EURL JB (2027) | L10: =Financement!B19 -> 50000
B12: 📈 SCÉNARIOS DE VENTES (Nombre d'ailes) | K12: TOTAL | L12: =SUM(L7:L10) -> 428000
C13: 2025 | D13: 2026 | E13: 2027 | F13: 2028 | G13: 2029 | H13: 2030 | I13: 2031
B14: 🟠 Réaliste | C14: 0 | D14: 75 | E14: 250 | F14: 550 | G14: 800 | H14: 1000 | I14: 1000 | K14: 📋 CHARGES FIXES / AN
B15: 🔴 Point Mort | C15: ='Analyse Point Mort'!B19 -> 0 | D15: ='Analyse Point Mort'!C19 -> 0 | E15: ='Analyse Point Mort'!D19 -> 139 | F15: ='Analyse Point Mort'!E19 -> 242 | G15: ='Analyse Point Mort'!F19 -> 242 | H15: ='Analyse Point Mort'!G19 -> 187 | I15: ='Analyse Point Mort'!H19 -> 187 | K15: Masse salariale | L15: ='Charges Fixes Plume'!D13 -> 83496
K16: Investissement R&D | L16: ='Charges Fixes Plume'!D38 -> 75128.734
K17: Exploitation | L17: ='Charges Fixes Plume'!D29 -> 50157.6
K19: TOTAL | L19: ='Charges Fixes Plume'!D57 -> 208782.33
B20: 💰 RÉSULTATS PRÉVISIONNELS - SCÉNARIO RÉALISTE
C21: 2025 | D21: 2026 | E21: 2027 | F21: 2028 | G21: 2029 | H21: 2030 | I21: 2031 | K21: 🏦 EMPRUNT BANCAIRE
B22: Chiffre d'affaires | C22: ='Compte de Résultat'!B13 -> 0 | D22: ='Compte de Résultat'!C13 -> 192906.25 | E22: ='Compte de Résultat'!D13 -> 643020.83 | F22: ='Compte de Résultat'!E13 -> 1414645.8 | G22: ='Compte de Résultat'!F13 -> 2057666.7 | H22: ='Compte de Résultat'!G13 -> 2572083.3 | I22: ='Compte de Résultat'!H13 -> 2700687.5 | K22: Montant | L22: ='Emprunt Bancaire'!B4 -> 189000
B23: bénéfice net | C23: ='Compte de Résultat'!B34 -> -8857.8558 | D23: ='Compte de Résultat'!C34 -> -128458.89 | E23: ='Compte de Résultat'!D34 -> 50265.066 | F23: ='Compte de Résultat'!E34 -> 382760.59 | G23: ='Compte de Résultat'!F34 -> 518386.01 | H23: ='Compte de Résultat'!G34 -> 690585.36 | I23: ='Compte de Résultat'!H34 -> 756513.57 | K23: Durée | L23: ='Emprunt Bancaire'!B5 -> 4
B24: Trésorerie cumulée | C24: ='Compte de Résultat'!B45 -> 91142.144 | D24: ='Compte de Résultat'!C45 -> 177292.44 | E24: ='Compte de Résultat'!D45 -> 195238.27 | F24: ='Compte de Résultat'!E45 -> 497335.69 | G24: ='Compte de Résultat'!F45 -> 1038336.3 | H24: ='Compte de Résultat'!G45 -> 1904663 | I24: ='Compte de Résultat'!H45 -> 2974177.6 | K24: Taux | L24: ='Emprunt Bancaire'!B6 -> 0.045
K25: Échéance/an | L25: ='Emprunt Bancaire'!D11 -> 52398.71
K27: ✅ POINTS CLÉS
K28: ✓ Rentabilité dès 2027
B29: "Le plan est présenté en euros constants (base 2025). L'inflation n'est pas modélisée séparément : les hausses de charges (salaires, matières, logistique) seront répercutées dans les prix de vente, maintenant les marges unitaires stables. Cette approche conservatrice sous-estime légèrement la rentabilité réelle, le remboursement d'emprunt étant fixe en euros nominaux." | K29: ✓ Seuil : ailes/an | L29: =F9 -> 204
K30: ✓ Marge brute | L30: ='Marges Produits'!G49 -> 0.42780787
K31: ✓ Tréso toujours positive
K32: ✓ Emprunt remboursé 2030

Sheet Frais de lancement
A1: PLUME PARAGLIDERS - CHARGES FIXES
A2: lancement
A5: 1. FRAIS DE LANCEMENT (One-shot)
A6: Poste | B6: Montant (€)
A7: Charte Graphique | B7: 500
A8: Création d'entreprise (Avocat) | B8: 3303
A9: SOUS-TOTAL LANCEMENT | B9: =SUM(B7:B8) -> 3803

Sheet Charges Fixes Plume
A1: PLUME PARAGLIDERS - CHARGES FIXES
A5: 1. MASSE SALARIALE ANNUELLE
A6: Note: ZFRR + ACRE. JB: prestation EURL 1 800€/mois. Thomas: 1 400€ brut/mois (coût employeur ~18 500€/an)
A7: Collaborateur | B7: Nb mois | C7: Type | D7: Charge annuelle (€) | F7: Mois décaissement | G7: Janvier | H7: Février | I7: Mars | J7: Avril | K7: Mai | L7: Juin | M7: Juillet | N7: Août | O7: Septembre | P7: Octobre | Q7: Novembre | R7: Décembre
A8: Manu Laly (pilote test) | B8: 10 | C8: Prestation | D8: 10000 | F8: Sauf Jul-Août | G8: =$D$8/10 -> 1000 | H8: =$D$8/10 -> 1000 | I8: =$D$8/10 -> 1000 | J8: =$D$8/10 -> 1000 | K8: =$D$8/10 -> 1000 | L8: =$D$8/10 -> 1000 | M8: 0 | N8: 0 | O8: =$D$8/10 -> 1000 | P8: =$D$8/10 -> 1000 | Q8: =$D$8/10 -> 1000 | R8: =$D$8/10 -> 1000
A9: Yann Freund (conception accessoire) | B9: 3 | C9: Prestation | D9: 6000 | F9: Jan à Mars | G9: =$D$9/3 -> 2000 | H9: =$D$9/3 -> 2000 | I9: =$D$9/3 -> 2000 | J9: 0 | K9: 0 | L9: 0 | M9: 0 | N9: 0 | O9: 0 | P9: 0 | Q9: 0 | R9: 0
A10: Jean-Baptiste Chandelier (president) | B10: 12 | C10: Prestation EURL | D10: 21600 | F10: Tous les mois | G10: =$D$10/12 -> 1800 | H10: =$D$10/12 -> 1800 | I10: =$D$10/12 -> 1800 | J10: =$D$10/12 -> 1800 | K10: =$D$10/12 -> 1800 | L10: =$D$10/12 -> 1800 | M10: =$D$10/12 -> 1800 | N10: =$D$10/12 -> 1800 | ... R10: =$D$10/12 -> 1800
A11: Thomas Pierre-Bes (directeur) | B11: 12 | C11: Salaire | D11: 18500 | F11: Tous les mois | G11: =$D$11/12 -> 1541.6667 | H11: =$D$11/12 -> 1541.6667 | I11: =$D$11/12 -> 1541.6667 | J11: =$D$11/12 -> 1541.6667 | K11: =$D$11/12 -> 1541.6667 | L11: =$D$11/12 -> 1541.6667 | M11: =$D$11/12 -> 1541.6667 | N11: =$D$11/12 -> 1541.6667 | ... R11: =$D$11/12 -> 1541.6667
A12: Jim Nougarolles (pilot test & R&D) | B12: 12 | C12: Prestation | D12: 27396 | F12: 1 mois sur 2 | G12: =$D$12/6 -> 4566 | H12: 0 | I12: =$D$12/6 -> 4566 | J12: 0 | K12: =$D$12/6 -> 4566 | L12: 0 | M12: =$D$12/6 -> 4566 | N12: 0 | O12: =$D$12/6 -> 4566 | P12: 0 | Q12: =$D$12/6 -> 4566 | R12: 0
A13: SOUS-TOTAL MASSE SALARIALE | D13: =SUM(D8:D12) -> 83496 | G13: =SUM(G8:G12) -> 10907.667 | H13: =SUM(H8:H12) -> 6341.6667 | I13: =SUM(I8:I12) -> 10907.667 | J13: =SUM(J8:J12) -> 4341.6667 | K13: =SUM(K8:K12) -> 8907.6667 | L13: =SUM(L8:L12) -> 4341.6667 | M13: =SUM(M8:M12) -> 7907.6667 | N13: =SUM(N8:N12) -> 3341.6667 | ... R13: =SUM(R8:R12) -> 4341.6667
A15: 2. CHARGES D'EXPLOITATION ANNUELLES (hors masse salariale)
A16: Poste | C16: Catégorie | D16: Montant (€/an) | E16: Fréquence | F16: Mois décaissement | G16: Janvier | H16: Février | I16: Mars | J16: Avril | K16: Mai | L16: Juin | M16: Juillet | N16: Août | O16: Septembre | P16: Octobre | Q16: Novembre | R16: Décembre
A17: OVH Website | C17: License | D17: 50 | E17: Annuel | F17: Décembre | G17: =IF($E17="Mensuel",$D17/12,IF($E17="Annuel",IF(G$16=$F17,$D17,0),IF($E17="Trimestriel",IF(OR(G$16="Janvier",G$16="Avril",G$16="Juillet",G$16="Octobre"),$D17/4,0),0))) -> 0 | H17: =IF($E17="Mensuel",$D17/12,IF($E17="Annuel",IF(H$16=$F17,$D17,0),IF($E17="Trimestriel",IF(OR(H$16="Janvier",H$16="Avril",H$16="Juillet",H$16="Octobre"),$D17/4,0),0))) -> 0 | I17: =IF($E17="Mensuel",$D17/12,IF($E17="Annuel",IF(I$16=$F17,$D17,0),IF($E17="Trimestriel",IF(OR(I$16="Janvier",I$16="Avril",I$16="Juillet",I$16="Octobre"),$D17/4,0),0))) -> 0 | J17: =IF($E17="Mensuel",$D17/12,IF($E17="Annuel",IF(J$16=$F17,$D17,0),IF($E17="Trimestriel",IF(OR(J$16="Janvier",J$16="Avril",J$16="Juillet",J$16="Octobre"),$D17/4,0),0))) -> 0 | K17: =IF($E17="Mensuel",$D17/12,IF($E17="Annuel",IF(K$16=$F17,$D17,0),IF($E17="Trimestriel",IF(OR(K$16="Janvier",K$16="Avril",K$16="Juillet",K$16="Octobre"),$D17/4,0),0))) -> 0 | L17: =IF($E17="Mensuel",$D17/12,IF($E17="Annuel",IF(L$16=$F17,$D17,0),IF($E17="Trimestriel",IF(OR(L$16="Janvier",L$16="Avril",L$16="Juillet",L$16="Octobre"),$D17/4,0),0))) -> 0 | M17: =IF($E17="Mensuel",$D17/12,IF($E17="Annuel",IF(M$16=$F17,$D17,0),IF($E17="Trimestriel",IF(OR(M$16="Janvier",M$16="Avril",M$16="Juillet",M$16="Octobre"),$D17/4,0),0))) -> 0 | N17: =IF($E17="Mensuel",$D17/12,IF($E17="Annuel",IF(N$16=$F17,$D17,0),IF($E17="Trimestriel",IF(OR(N$16="Janvier",N$16="Avril",N$16="Juillet",N$16="Octobre"),$D17/4,0),0))) -> 0 | ... R17: =IF($E17="Mensuel",$D17/12,IF($E17="Annuel",IF(R$16=$F17,$D17,0),IF($E17="Trimestriel",IF(OR(R$16="Janvier",R$16="Avril",R$16="Juillet",R$16="Octobre"),$D17/4,0),0))) -> 50
A18: Déplacements / Nourriture / Logement | C18: Déplacement | D18: 10000 | E18: Mensuel | F18: Tous les mois | G18: =IF($E18="Mensuel",$D18/12,IF($E18="Annuel",IF(G$16=$F18,$D18,0),IF($E18="Trimestriel",IF(OR(G$16="Janvier",G$16="Avril",G$16="Juillet",G$16="Octobre"),$D18/4,0),0))) -> 833.33333 | H18: =IF($E18="Mensuel",$D18/12,IF($E18="Annuel",IF(H$16=$F18,$D18,0),IF($E18="Trimestriel",IF(OR(H$16="Janvier",H$16="Avril",H$16="Juillet",H$16="Octobre"),$D18/4,0),0))) -> 833.33333 | I18: =IF($E18="Mensuel",$D18/12,IF($E18="Annuel",IF(I$16=$F18,$D18,0),IF($E18="Trimestriel",IF(OR(I$16="Janvier",I$16="Avril",I$16="Juillet",I$16="Octobre"),$D18/4,0),0))) -> 833.33333 | J18: =IF($E18="Mensuel",$D18/12,IF($E18="Annuel",IF(J$16=$F18,$D18,0),IF($E18="Trimestriel",IF(OR(J$16="Janvier",J$16="Avril",J$16="Juillet",J$16="Octobre"),$D18/4,0),0))) -> 833.33333 | K18: =IF($E18="Mensuel",$D18/12,IF($E18="Annuel",IF(K$16=$F18,$D18,0),IF($E18="Trimestriel",IF(OR(K$16="Janvier",K$16="Avril",K$16="Juillet",K$16="Octobre"),$D18/4,0),0))) -> 833.33333 | L18: =IF($E18="Mensuel",$D18/12,IF($E18="Annuel",IF(L$16=$F18,$D18,0),IF($E18="Trimestriel",IF(OR(L$16="Janvier",L$16="Avril",L$16="Juillet",L$16="Octobre"),$D18/4,0),0))) -> 833.33333 | M18: =IF($E18="Mensuel",$D18/12,IF($E18="Annuel",IF(M$16=$F18,$D18,0),IF($E18="Trimestriel",IF(OR(M$16="Janvier",M$16="Avril",M$16="Juillet",M$16="Octobre"),$D18/4,0),0))) -> 833.33333 | N18: =IF($E18="Mensuel",$D18/12,IF($E18="Annuel",IF(N$16=$F18,$D18,0),IF($E18="Trimestriel",IF(OR(N$16="Janvier",N$16="Avril",N$16="Juillet",N$16="Octobre"),$D18/4,0),0))) -> 833.33333 | ... R18: =IF($E18="Mensuel",$D18/12,IF($E18="Annuel",IF(R$16=$F18,$D18,0),IF($E18="Trimestriel",IF(OR(R$16="Janvier",R$16="Avril",R$16="Juillet",R$16="Octobre"),$D18/4,0),0))) -> 833.33333
A19: Adobe | C19: Logiciel | D19: 660 | E19: Mensuel | F19: Tous les mois | G19: =IF($E19="Mensuel",$D19/12,IF($E19="Annuel",IF(G$16=$F19,$D19,0),IF($E19="Trimestriel",IF(OR(G$16="Janvier",G$16="Avril",G$16="Juillet",G$16="Octobre"),$D19/4,0),0))) -> 55 | H19: =IF($E19="Mensuel",$D19/12,IF($E19="Annuel",IF(H$16=$F19,$D19,0),IF($E19="Trimestriel",IF(OR(H$16="Janvier",H$16="Avril",H$16="Juillet",H$16="Octobre"),$D19/4,0),0))) -> 55 | I19: =IF($E19="Mensuel",$D19/12,IF($E19="Annuel",IF(I$16=$F19,$D19,0),IF($E19="Trimestriel",IF(OR(I$16="Janvier",I$16="Avril",I$16="Juillet",I$16="Octobre"),$D19/4,0),0))) -> 55 | J19: =IF($E19="Mensuel",$D19/12,IF($E19="Annuel",IF(J$16=$F19,$D19,0),IF($E19="Trimestriel",IF(OR(J$16="Janvier",J$16="Avril",J$16="Juillet",J$16="Octobre"),$D19/4,0),0))) -> 55 | K19: =IF($E19="Mensuel",$D19/12,IF($E19="Annuel",IF(K$16=$F19,$D19,0),IF($E19="Trimestriel",IF(OR(K$16="Janvier",K$16="Avril",K$16="Juillet",K$16="Octobre"),$D19/4,0),0))) -> 55 | L19: =IF($E19="Mensuel",$D19/12,IF($E19="Annuel",IF(L$16=$F19,$D19,0),IF($E19="Trimestriel",IF(OR(L$16="Janvier",L$16="Avril",L$16="Juillet",L$16="Octobre"),$D19/4,0),0))) -> 55 | M19: =IF($E19="Mensuel",$D19/12,IF($E19="Annuel",IF(M$16=$F19,$D19,0),IF($E19="Trimestriel",IF(OR(M$16="Janvier",M$16="Avril",M$16="Juillet",M$16="Octobre"),$D19/4,0),0))) -> 55 | N19: =IF($E19="Mensuel",$D19/12,IF($E19="Annuel",IF(N$16=$F19,$D19,0),IF($E19="Trimestriel",IF(OR(N$16="Janvier",N$16="Avril",N$16="Juillet",N$16="Octobre"),$D19/4,0),0))) -> 55 | ... R19: =IF($E19="Mensuel",$D19/12,IF($E19="Annuel",IF(R$16=$F19,$D19,0),IF($E19="Trimestriel",IF(OR(R$16="Janvier",R$16="Avril",R$16="Juillet",R$16="Octobre"),$D19/4,0),0))) -> 55
A20: Microsoft Teams / Cloud / Suite Office | C20: Logiciel | D20: 777.6 | E20: Mensuel | F20: Tous les mois | G20: =IF($E20="Mensuel",$D20/12,IF($E20="Annuel",IF(G$16=$F20,$D20,0),IF($E20="Trimestriel",IF(OR(G$16="Janvier",G$16="Avril",G$16="Juillet",G$16="Octobre"),$D20/4,0),0))) -> 64.8 | H20: =IF($E20="Mensuel",$D20/12,IF($E20="Annuel",IF(H$16=$F20,$D20,0),IF($E20="Trimestriel",IF(OR(H$16="Janvier",H$16="Avril",H$16="Juillet",H$16="Octobre"),$D20/4,0),0))) -> 64.8 | I20: =IF($E20="Mensuel",$D20/12,IF($E20="Annuel",IF(I$16=$F20,$D20,0),IF($E20="Trimestriel",IF(OR(I$16="Janvier",I$16="Avril",I$16="Juillet",I$16="Octobre"),$D20/4,0),0))) -> 64.8 | J20: =IF($E20="Mensuel",$D20/12,IF($E20="Annuel",IF(J$16=$F20,$D20,0),IF($E20="Trimestriel",IF(OR(J$16="Janvier",J$16="Avril",J$16="Juillet",J$16="Octobre"),$D20/4,0),0))) -> 64.8 | K20: =IF($E20="Mensuel",$D20/12,IF($E20="Annuel",IF(K$16=$F20,$D20,0),IF($E20="Trimestriel",IF(OR(K$16="Janvier",K$16="Avril",K$16="Juillet",K$16="Octobre"),$D20/4,0),0))) -> 64.8 | L20: =IF($E20="Mensuel",$D20/12,IF($E20="Annuel",IF(L$16=$F20,$D20,0),IF($E20="Trimestriel",IF(OR(L$16="Janvier",L$16="Avril",L$16="Juillet",L$16="Octobre"),$D20/4,0),0))) -> 64.8 | M20: =IF($E20="Mensuel",$D20/12,IF($E20="Annuel",IF(M$16=$F20,$D20,0),IF($E20="Trimestriel",IF(OR(M$16="Janvier",M$16="Avril",M$16="Juillet",M$16="Octobre"),$D20/4,0),0))) -> 64.8 | N20: =IF($E20="Mensuel",$D20/12,IF($E20="Annuel",IF(N$16=$F20,$D20,0),IF($E20="Trimestriel",IF(OR(N$16="Janvier",N$16="Avril",N$16="Juillet",N$16="Octobre"),$D20/4,0),0))) -> 64.8 | ... R20: =IF($E20="Mensuel",$D20/12,IF($E20="Annuel",IF(R$16=$F20,$D20,0),IF($E20="Trimestriel",IF(OR(R$16="Janvier",R$16="Avril",R$16="Juillet",R$16="Octobre"),$D20/4,0),0))) -> 64.8
A21: Loyer Briançon (3bis Route de Gap) | C21: Frais fixe | D21: 9600 | E21: Mensuel | F21: Tous les mois | G21: =IF($E21="Mensuel",$D21/12,IF($E21="Annuel",IF(G$16=$F21,$D21,0),IF($E21="Trimestriel",IF(OR(G$16="Janvier",G$16="Avril",G$16="Juillet",G$16="Octobre"),$D21/4,0),0))) -> 800 | H21: =IF($E21="Mensuel",$D21/12,IF($E21="Annuel",IF(H$16=$F21,$D21,0),IF($E21="Trimestriel",IF(OR(H$16="Janvier",H$16="Avril",H$16="Juillet",H$16="Octobre"),$D21/4,0),0))) -> 800 | I21: =IF($E21="Mensuel",$D21/12,IF($E21="Annuel",IF(I$16=$F21,$D21,0),IF($E21="Trimestriel",IF(OR(I$16="Janvier",I$16="Avril",I$16="Juillet",I$16="Octobre"),$D21/4,0),0))) -> 800 | J21: =IF($E21="Mensuel",$D21/12,IF($E21="Annuel",IF(J$16=$F21,$D21,0),IF($E21="Trimestriel",IF(OR(J$16="Janvier",J$16="Avril",J$16="Juillet",J$16="Octobre"),$D21/4,0),0))) -> 800 | K21: =IF($E21="Mensuel",$D21/12,IF($E21="Annuel",IF(K$16=$F21,$D21,0),IF($E21="Trimestriel",IF(OR(K$16="Janvier",K$16="Avril",K$16="Juillet",K$16="Octobre"),$D21/4,0),0))) -> 800 | L21: =IF($E21="Mensuel",$D21/12,IF($E21="Annuel",IF(L$16=$F21,$D21,0),IF($E21="Trimestriel",IF(OR(L$16="Janvier",L$16="Avril",L$16="Juillet",L$16="Octobre"),$D21/4,0),0))) -> 800 | M21: =IF($E21="Mensuel",$D21/12,IF($E21="Annuel",IF(M$16=$F21,$D21,0),IF($E21="Trimestriel",IF(OR(M$16="Janvier",M$16="Avril",M$16="Juillet",M$16="Octobre"),$D21/4,0),0))) -> 800 | N21: =IF($E21="Mensuel",$D21/12,IF($E21="Annuel",IF(N$16=$F21,$D21,0),IF($E21="Trimestriel",IF(OR(N$16="Janvier",N$16="Avril",N$16="Juillet",N$16="Octobre"),$D21/4,0),0))) -> 800 | ... R21: =IF($E21="Mensuel",$D21/12,IF($E21="Annuel",IF(R$16=$F21,$D21,0),IF($E21="Trimestriel",IF(OR(R$16="Janvier",R$16="Avril",R$16="Juillet",R$16="Octobre"),$D21/4,0),0))) -> 800
A22: Loyer bureau/atelier Embrun | C22: Frais fixe | D22: 3600 | E22: Mensuel | F22: Tous les mois | G22: =IF($E22="Mensuel",$D22/12,IF($E22="Annuel",IF(G$16=$F22,$D22,0),IF($E22="Trimestriel",IF(OR(G$16="Janvier",G$16="Avril",G$16="Juillet",G$16="Octobre"),$D22/4,0),0))) -> 300 | H22: =IF($E22="Mensuel",$D22/12,IF($E22="Annuel",IF(H$16=$F22,$D22,0),IF($E22="Trimestriel",IF(OR(H$16="Janvier",H$16="Avril",H$16="Juillet",H$16="Octobre"),$D22/4,0),0))) -> 300 | I22: =IF($E22="Mensuel",$D22/12,IF($E22="Annuel",IF(I$16=$F22,$D22,0),IF($E22="Trimestriel",IF(OR(I$16="Janvier",I$16="Avril",I$16="Juillet",I$16="Octobre"),$D22/4,0),0))) -> 300 | J22: =IF($E22="Mensuel",$D22/12,IF($E22="Annuel",IF(J$16=$F22,$D22,0),IF($E22="Trimestriel",IF(OR(J$16="Janvier",J$16="Avril",J$16="Juillet",J$16="Octobre"),$D22/4,0),0))) -> 300 | K22: =IF($E22="Mensuel",$D22/12,IF($E22="Annuel",IF(K$16=$F22,$D22,0),IF($E22="Trimestriel",IF(OR(K$16="Janvier",K$16="Avril",K$16="Juillet",K$16="Octobre"),$D22/4,0),0))) -> 300 | L22: =IF($E22="Mensuel",$D22/12,IF($E22="Annuel",IF(L$16=$F22,$D22,0),IF($E22="Trimestriel",IF(OR(L$16="Janvier",L$16="Avril",L$16="Juillet",L$16="Octobre"),$D22/4,0),0))) -> 300 | M22: =IF($E22="Mensuel",$D22/12,IF($E22="Annuel",IF(M$16=$F22,$D22,0),IF($E22="Trimestriel",IF(OR(M$16="Janvier",M$16="Avril",M$16="Juillet",M$16="Octobre"),$D22/4,0),0))) -> 300 | N22: =IF($E22="Mensuel",$D22/12,IF($E22="Annuel",IF(N$16=$F22,$D22,0),IF($E22="Trimestriel",IF(OR(N$16="Janvier",N$16="Avril",N$16="Juillet",N$16="Octobre"),$D22/4,0),0))) -> 300 | ... R22: =IF($E22="Mensuel",$D22/12,IF($E22="Annuel",IF(R$16=$F22,$D22,0),IF($E22="Trimestriel",IF(OR(R$16="Janvier",R$16="Avril",R$16="Juillet",R$16="Octobre"),$D22/4,0),0))) -> 300
A23: Indemnités kilométriques Thomas (Embrun ↔ Briançon, 12 480 km/an) | C23: Déplacement | D23: 5850 | E23: Mensuel | F23: Tous les mois | G23: =IF($E23="Mensuel",$D23/12,IF($E23="Annuel",IF(G$16=$F23,$D23,0),IF($E23="Trimestriel",IF(OR(G$16="Janvier",G$16="Avril",G$16="Juillet",G$16="Octobre"),$D23/4,0),0))) -> 487.5 | H23: =IF($E23="Mensuel",$D23/12,IF($E23="Annuel",IF(H$16=$F23,$D23,0),IF($E23="Trimestriel",IF(OR(H$16="Janvier",H$16="Avril",H$16="Juillet",H$16="Octobre"),$D23/4,0),0))) -> 487.5 | I23: =IF($E23="Mensuel",$D23/12,IF($E23="Annuel",IF(I$16=$F23,$D23,0),IF($E23="Trimestriel",IF(OR(I$16="Janvier",I$16="Avril",I$16="Juillet",I$16="Octobre"),$D23/4,0),0))) -> 487.5 | J23: =IF($E23="Mensuel",$D23/12,IF($E23="Annuel",IF(J$16=$F23,$D23,0),IF($E23="Trimestriel",IF(OR(J$16="Janvier",J$16="Avril",J$16="Juillet",J$16="Octobre"),$D23/4,0),0))) -> 487.5 | K23: =IF($E23="Mensuel",$D23/12,IF($E23="Annuel",IF(K$16=$F23,$D23,0),IF($E23="Trimestriel",IF(OR(K$16="Janvier",K$16="Avril",K$16="Juillet",K$16="Octobre"),$D23/4,0),0))) -> 487.5 | L23: =IF($E23="Mensuel",$D23/12,IF($E23="Annuel",IF(L$16=$F23,$D23,0),IF($E23="Trimestriel",IF(OR(L$16="Janvier",L$16="Avril",L$16="Juillet",L$16="Octobre"),$D23/4,0),0))) -> 487.5 | M23: =IF($E23="Mensuel",$D23/12,IF($E23="Annuel",IF(M$16=$F23,$D23,0),IF($E23="Trimestriel",IF(OR(M$16="Janvier",M$16="Avril",M$16="Juillet",M$16="Octobre"),$D23/4,0),0))) -> 487.5 | N23: =IF($E23="Mensuel",$D23/12,IF($E23="Annuel",IF(N$16=$F23,$D23,0),IF($E23="Trimestriel",IF(OR(N$16="Janvier",N$16="Avril",N$16="Juillet",N$16="Octobre"),$D23/4,0),0))) -> 487.5 | ... R23: =IF($E23="Mensuel",$D23/12,IF($E23="Annuel",IF(R$16=$F23,$D23,0),IF($E23="Trimestriel",IF(OR(R$16="Janvier",R$16="Avril",R$16="Juillet",R$16="Octobre"),$D23/4,0),0))) -> 487.5
A24: Notion | C24: Gestion | D24: 570 | E24: Annuel | F24: Février | G24: =IF($E24="Mensuel",$D24/12,IF($E24="Annuel",IF(G$16=$F24,$D24,0),IF($E24="Trimestriel",IF(OR(G$16="Janvier",G$16="Avril",G$16="Juillet",G$16="Octobre"),$D24/4,0),0))) -> 0 | H24: =IF($E24="Mensuel",$D24/12,IF($E24="Annuel",IF(H$16=$F24,$D24,0),IF($E24="Trimestriel",IF(OR(H$16="Janvier",H$16="Avril",H$16="Juillet",H$16="Octobre"),$D24/4,0),0))) -> 570 | I24: =IF($E24="Mensuel",$D24/12,IF($E24="Annuel",IF(I$16=$F24,$D24,0),IF($E24="Trimestriel",IF(OR(I$16="Janvier",I$16="Avril",I$16="Juillet",I$16="Octobre"),$D24/4,0),0))) -> 0 | J24: =IF($E24="Mensuel",$D24/12,IF($E24="Annuel",IF(J$16=$F24,$D24,0),IF($E24="Trimestriel",IF(OR(J$16="Janvier",J$16="Avril",J$16="Juillet",J$16="Octobre"),$D24/4,0),0))) -> 0 | K24: =IF($E24="Mensuel",$D24/12,IF($E24="Annuel",IF(K$16=$F24,$D24,0),IF($E24="Trimestriel",IF(OR(K$16="Janvier",K$16="Avril",K$16="Juillet",K$16="Octobre"),$D24/4,0),0))) -> 0 | L24: =IF($E24="Mensuel",$D24/12,IF($E24="Annuel",IF(L$16=$F24,$D24,0),IF($E24="Trimestriel",IF(OR(L$16="Janvier",L$16="Avril",L$16="Juillet",L$16="Octobre"),$D24/4,0),0))) -> 0 | M24: =IF($E24="Mensuel",$D24/12,IF($E24="Annuel",IF(M$16=$F24,$D24,0),IF($E24="Trimestriel",IF(OR(M$16="Janvier",M$16="Avril",M$16="Juillet",M$16="Octobre"),$D24/4,0),0))) -> 0 | N24: =IF($E24="Mensuel",$D24/12,IF($E24="Annuel",IF(N$16=$F24,$D24,0),IF($E24="Trimestriel",IF(OR(N$16="Janvier",N$16="Avril",N$16="Juillet",N$16="Octobre"),$D24/4,0),0))) -> 0 | ... R24: =IF($E24="Mensuel",$D24/12,IF($E24="Annuel",IF(R$16=$F24,$D24,0),IF($E24="Trimestriel",IF(OR(R$16="Janvier",R$16="Avril",R$16="Juillet",R$16="Octobre"),$D24/4,0),0))) -> 0
A25: AI Assistant | C25: Logiciel | D25: 5400 | E25: Mensuel | F25: Tous les mois | G25: =IF($E25="Mensuel",$D25/12,IF($E25="Annuel",IF(G$16=$F25,$D25,0),IF($E25="Trimestriel",IF(OR(G$16="Janvier",G$16="Avril",G$16="Juillet",G$16="Octobre"),$D25/4,0),0))) -> 450 | H25: =IF($E25="Mensuel",$D25/12,IF($E25="Annuel",IF(H$16=$F25,$D25,0),IF($E25="Trimestriel",IF(OR(H$16="Janvier",H$16="Avril",H$16="Juillet",H$16="Octobre"),$D25/4,0),0))) -> 450 | I25: =IF($E25="Mensuel",$D25/12,IF($E25="Annuel",IF(I$16=$F25,$D25,0),IF($E25="Trimestriel",IF(OR(I$16="Janvier",I$16="Avril",I$16="Juillet",I$16="Octobre"),$D25/4,0),0))) -> 450 | J25: =IF($E25="Mensuel",$D25/12,IF($E25="Annuel",IF(J$16=$F25,$D25,0),IF($E25="Trimestriel",IF(OR(J$16="Janvier",J$16="Avril",J$16="Juillet",J$16="Octobre"),$D25/4,0),0))) -> 450 | K25: =IF($E25="Mensuel",$D25/12,IF($E25="Annuel",IF(K$16=$F25,$D25,0),IF($E25="Trimestriel",IF(OR(K$16="Janvier",K$16="Avril",K$16="Juillet",K$16="Octobre"),$D25/4,0),0))) -> 450 | L25: =IF($E25="Mensuel",$D25/12,IF($E25="Annuel",IF(L$16=$F25,$D25,0),IF($E25="Trimestriel",IF(OR(L$16="Janvier",L$16="Avril",L$16="Juillet",L$16="Octobre"),$D25/4,0),0))) -> 450 | M25: =IF($E25="Mensuel",$D25/12,IF($E25="Annuel",IF(M$16=$F25,$D25,0),IF($E25="Trimestriel",IF(OR(M$16="Janvier",M$16="Avril",M$16="Juillet",M$16="Octobre"),$D25/4,0),0))) -> 450 | N25: =IF($E25="Mensuel",$D25/12,IF($E25="Annuel",IF(N$16=$F25,$D25,0),IF($E25="Trimestriel",IF(OR(N$16="Janvier",N$16="Avril",N$16="Juillet",N$16="Octobre"),$D25/4,0),0))) -> 450 | ... R25: =IF($E25="Mensuel",$D25/12,IF($E25="Annuel",IF(R$16=$F25,$D25,0),IF($E25="Trimestriel",IF(OR(R$16="Janvier",R$16="Avril",R$16="Juillet",R$16="Octobre"),$D25/4,0),0))) -> 450
A26: Glider Plan | C26: Logiciel | D26: 4650 | E26: Annuel | F26: Janvier | G26: =IF($E26="Mensuel",$D26/12,IF($E26="Annuel",IF(G$16=$F26,$D26,0),IF($E26="Trimestriel",IF(OR(G$16="Janvier",G$16="Avril",G$16="Juillet",G$16="Octobre"),$D26/4,0),0))) -> 4650 | H26: =IF($E26="Mensuel",$D26/12,IF($E26="Annuel",IF(H$16=$F26,$D26,0),IF($E26="Trimestriel",IF(OR(H$16="Janvier",H$16="Avril",H$16="Juillet",H$16="Octobre"),$D26/4,0),0))) -> 0 | I26: =IF($E26="Mensuel",$D26/12,IF($E26="Annuel",IF(I$16=$F26,$D26,0),IF($E26="Trimestriel",IF(OR(I$16="Janvier",I$16="Avril",I$16="Juillet",I$16="Octobre"),$D26/4,0),0))) -> 0 | J26: =IF($E26="Mensuel",$D26/12,IF($E26="Annuel",IF(J$16=$F26,$D26,0),IF($E26="Trimestriel",IF(OR(J$16="Janvier",J$16="Avril",J$16="Juillet",J$16="Octobre"),$D26/4,0),0))) -> 0 | K26: =IF($E26="Mensuel",$D26/12,IF($E26="Annuel",IF(K$16=$F26,$D26,0),IF($E26="Trimestriel",IF(OR(K$16="Janvier",K$16="Avril",K$16="Juillet",K$16="Octobre"),$D26/4,0),0))) -> 0 | L26: =IF($E26="Mensuel",$D26/12,IF($E26="Annuel",IF(L$16=$F26,$D26,0),IF($E26="Trimestriel",IF(OR(L$16="Janvier",L$16="Avril",L$16="Juillet",L$16="Octobre"),$D26/4,0),0))) -> 0 | M26: =IF($E26="Mensuel",$D26/12,IF($E26="Annuel",IF(M$16=$F26,$D26,0),IF($E26="Trimestriel",IF(OR(M$16="Janvier",M$16="Avril",M$16="Juillet",M$16="Octobre"),$D26/4,0),0))) -> 0 | N26: =IF($E26="Mensuel",$D26/12,IF($E26="Annuel",IF(N$16=$F26,$D26,0),IF($E26="Trimestriel",IF(OR(N$16="Janvier",N$16="Avril",N$16="Juillet",N$16="Octobre"),$D26/4,0),0))) -> 0 | ... R26: =IF($E26="Mensuel",$D26/12,IF($E26="Annuel",IF(R$16=$F26,$D26,0),IF($E26="Trimestriel",IF(OR(R$16="Janvier",R$16="Avril",R$16="Juillet",R$16="Octobre"),$D26/4,0),0))) -> 0
A27: Investissement matériel | C27: Achat | D27: 5000 | E27: Mensuel | F27: Tous les mois | G27: =IF($E27="Mensuel",$D27/12,IF($E27="Annuel",IF(G$16=$F27,$D27,0),IF($E27="Trimestriel",IF(OR(G$16="Janvier",G$16="Avril",G$16="Juillet",G$16="Octobre"),$D27/4,0),0))) -> 416.66667 | H27: =IF($E27="Mensuel",$D27/12,IF($E27="Annuel",IF(H$16=$F27,$D27,0),IF($E27="Trimestriel",IF(OR(H$16="Janvier",H$16="Avril",H$16="Juillet",H$16="Octobre"),$D27/4,0),0))) -> 416.66667 | I27: =IF($E27="Mensuel",$D27/12,IF($E27="Annuel",IF(I$16=$F27,$D27,0),IF($E27="Trimestriel",IF(OR(I$16="Janvier",I$16="Avril",I$16="Juillet",I$16="Octobre"),$D27/4,0),0))) -> 416.66667 | J27: =IF($E27="Mensuel",$D27/12,IF($E27="Annuel",IF(J$16=$F27,$D27,0),IF($E27="Trimestriel",IF(OR(J$16="Janvier",J$16="Avril",J$16="Juillet",J$16="Octobre"),$D27/4,0),0))) -> 416.66667 | K27: =IF($E27="Mensuel",$D27/12,IF($E27="Annuel",IF(K$16=$F27,$D27,0),IF($E27="Trimestriel",IF(OR(K$16="Janvier",K$16="Avril",K$16="Juillet",K$16="Octobre"),$D27/4,0),0))) -> 416.66667 | L27: =IF($E27="Mensuel",$D27/12,IF($E27="Annuel",IF(L$16=$F27,$D27,0),IF($E27="Trimestriel",IF(OR(L$16="Janvier",L$16="Avril",L$16="Juillet",L$16="Octobre"),$D27/4,0),0))) -> 416.66667 | M27: =IF($E27="Mensuel",$D27/12,IF($E27="Annuel",IF(M$16=$F27,$D27,0),IF($E27="Trimestriel",IF(OR(M$16="Janvier",M$16="Avril",M$16="Juillet",M$16="Octobre"),$D27/4,0),0))) -> 416.66667 | N27: =IF($E27="Mensuel",$D27/12,IF($E27="Annuel",IF(N$16=$F27,$D27,0),IF($E27="Trimestriel",IF(OR(N$16="Janvier",N$16="Avril",N$16="Juillet",N$16="Octobre"),$D27/4,0),0))) -> 416.66667 | ... R27: =IF($E27="Mensuel",$D27/12,IF($E27="Annuel",IF(R$16=$F27,$D27,0),IF($E27="Trimestriel",IF(OR(R$16="Janvier",R$16="Avril",R$16="Juillet",R$16="Octobre"),$D27/4,0),0))) -> 416.66667
A28: Comptabilité | C28: Gestion | D28: 4000 | E28: Trimestriel | F28: Jan/Avr/Jul/Oct | G28: =IF($E28="Mensuel",$D28/12,IF($E28="Annuel",IF(G$16=$F28,$D28,0),IF($E28="Trimestriel",IF(OR(G$16="Janvier",G$16="Avril",G$16="Juillet",G$16="Octobre"),$D28/4,0),0))) -> 1000 | H28: =IF($E28="Mensuel",$D28/12,IF($E28="Annuel",IF(H$16=$F28,$D28,0),IF($E28="Trimestriel",IF(OR(H$16="Janvier",H$16="Avril",H$16="Juillet",H$16="Octobre"),$D28/4,0),0))) -> 0 | I28: =IF($E28="Mensuel",$D28/12,IF($E28="Annuel",IF(I$16=$F28,$D28,0),IF($E28="Trimestriel",IF(OR(I$16="Janvier",I$16="Avril",I$16="Juillet",I$16="Octobre"),$D28/4,0),0))) -> 0 | J28: =IF($E28="Mensuel",$D28/12,IF($E28="Annuel",IF(J$16=$F28,$D28,0),IF($E28="Trimestriel",IF(OR(J$16="Janvier",J$16="Avril",J$16="Juillet",J$16="Octobre"),$D28/4,0),0))) -> 1000 | K28: =IF($E28="Mensuel",$D28/12,IF($E28="Annuel",IF(K$16=$F28,$D28,0),IF($E28="Trimestriel",IF(OR(K$16="Janvier",K$16="Avril",K$16="Juillet",K$16="Octobre"),$D28/4,0),0))) -> 0 | L28: =IF($E28="Mensuel",$D28/12,IF($E28="Annuel",IF(L$16=$F28,$D28,0),IF($E28="Trimestriel",IF(OR(L$16="Janvier",L$16="Avril",L$16="Juillet",L$16="Octobre"),$D28/4,0),0))) -> 0 | M28: =IF($E28="Mensuel",$D28/12,IF($E28="Annuel",IF(M$16=$F28,$D28,0),IF($E28="Trimestriel",IF(OR(M$16="Janvier",M$16="Avril",M$16="Juillet",M$16="Octobre"),$D28/4,0),0))) -> 1000 | N28: =IF($E28="Mensuel",$D28/12,IF($E28="Annuel",IF(N$16=$F28,$D28,0),IF($E28="Trimestriel",IF(OR(N$16="Janvier",N$16="Avril",N$16="Juillet",N$16="Octobre"),$D28/4,0),0))) -> 0 | ... R28: =IF($E28="Mensuel",$D28/12,IF($E28="Annuel",IF(R$16=$F28,$D28,0),IF($E28="Trimestriel",IF(OR(R$16="Janvier",R$16="Avril",R$16="Juillet",R$16="Octobre"),$D28/4,0),0))) -> 0
A29: SOUS-TOTAL EXPLOITATION | D29: =SUM(D17:D28) -> 50157.6 | G29: =SUM(G17:G28) -> 9057.3 | H29: =SUM(H17:H28) -> 3977.3 | I29: =SUM(I17:I28) -> 3407.3 | J29: =SUM(J17:J28) -> 4407.3 | K29: =SUM(K17:K28) -> 3407.3 | L29: =SUM(L17:L28) -> 3407.3 | M29: =SUM(M17:M28) -> 4407.3 | N29: =SUM(N17:N28) -> 3407.3 | ... R29: =SUM(R17:R28) -> 3457.3
A32: 3. INVESTISSEMENT R&D ANNUEL
A33: Poste | B33: Nb protos | C33: Prix unitaire (€) | D33: Coût total (€) | F33: Mois décaissement | G33: Janvier | H33: Février | I33: Mars | J33: Avril | K33: Mai | L33: Juin | M33: Juillet | N33: Août | O33: Septembre | P33: Octobre | Q33: Novembre | R33: Décembre
A34: Proto recherche | B34: 24 | C34: ='Marges Produits'!E49*1.2 -> 1258.551 | D34: =B34*C34 -> 30205.224 | F34: 2 protos/mois | G34: 10000 | H34: 0 | I34: 0 | J34: 0 | K34: =$D$34/12 -> 2517.102 | L34: =$D$34/12 -> 2517.102 | M34: =$D$34/12 -> 2517.102 | N34: =$D$34/12 -> 2517.102 | O34: =$D$34/12 -> 2517.102 | P34: =$D$34/12 -> 2517.102 | Q34: =$D$34/12 -> 2517.102 | R34: =$D$34/12 -> 2517.102
A35: Veille concurrentielle | B35: 2 | C35: 2500 | D35: =B35*C35 -> 5000 | F35: Jan + Jul | G35: =$C$35 -> 2500 | H35: 0 | I35: 0 | J35: 0 | K35: 0 | L35: 0 | M35: =$C$35 -> 2500 | N35: 0 | O35: 0 | P35: 0 | Q35: 0 | R35: 0
A36: Pré-série homologation | B36: 10 | C36: =C34 -> 1258.551 | D36: =B36*C36 -> 12585.51 | F36: Avr + Août | G36: 0 | H36: 0 | I36: 0 | J36: =$D$36/2 -> 6292.755 | K36: 0 | L36: 0 | M36: 0 | N36: =$D$36/2 -> 6292.755 | O36: 0 | P36: 0 | Q36: 0 | R36: 0
A37: Homologation | B37: 2 | C37: 13669 | D37: =B37*C37 -> 27338 | F37: Avr + Août | G37: 0 | H37: 0 | I37: 0 | J37: =$C$37 -> 13669 | K37: 0 | L37: 0 | M37: 0 | N37: =C37 -> 13669 | O37: 0 | P37: 0 | Q37: 0 | R37: 0
A38: SOUS-TOTAL R&D | D38: =SUM(D34:D37) -> 75128.734 | G38: =SUM(G34:G37) -> 12500 | H38: =SUM(H34:H37) -> 0 | I38: =SUM(I34:I37) -> 0 | J38: =SUM(J34:J37) -> 19961.755 | K38: =SUM(K34:K37) -> 2517.102 | L38: =SUM(L34:L37) -> 2517.102 | M38: =SUM(M34:M37) -> 5017.102 | N38: =SUM(N34:N37) -> 22478.857 | ... R38: =SUM(R34:R37) -> 2517.102
A41: 4. CHARGES DE CROISSANCE
A42: ⚡ Déclencheur : activées à partir de 2029 (dès que N-1 > 500 ailes vendues)
A43: Poste | C43: Catégorie | D43: Montant (€/an) | E43: Fréquence | F43: Mois décaissement | G43: Janvier | H43: Février | I43: Mars | J43: Avril | K43: Mai | L43: Juin | M43: Juillet | N43: Août | O43: Septembre | P43: Octobre | Q43: Novembre | R43: Décembre
A44: Revalorisation JB (EURL : 1 800 → 3 000€/mois) | C44: Prestation | D44: 14400 | E44: Mensuel | F44: Tous les mois | G44: =$D44/12 -> 1200 | H44: =$D44/12 -> 1200 | I44: =$D44/12 -> 1200 | J44: =$D44/12 -> 1200 | K44: =$D44/12 -> 1200 | L44: =$D44/12 -> 1200 | M44: =$D44/12 -> 1200 | N44: =$D44/12 -> 1200 | ... R44: =$D44/12 -> 1200
A45: Revalorisation Thomas (1 400 → 3 200€ brut/mois) | C45: Salaire | D45: 23500 | E45: Mensuel | F45: Tous les mois | G45: =$D45/12 -> 1958.3333 | H45: =$D45/12 -> 1958.3333 | I45: =$D45/12 -> 1958.3333 | J45: =$D45/12 -> 1958.3333 | K45: =$D45/12 -> 1958.3333 | L45: =$D45/12 -> 1958.3333 | M45: =$D45/12 -> 1958.3333 | N45: =$D45/12 -> 1958.3333 | ... R45: =$D45/12 -> 1958.3333
A46: Jim — passage salarié (presta 27 396 → salarié 42 000€) | C46: Salaire | D46: 14604 | E46: Mensuel | F46: Tous les mois | G46: =$D46/12 -> 1217 | H46: =$D46/12 -> 1217 | I46: =$D46/12 -> 1217 | J46: =$D46/12 -> 1217 | K46: =$D46/12 -> 1217 | L46: =$D46/12 -> 1217 | M46: =$D46/12 -> 1217 | N46: =$D46/12 -> 1217 | ... R46: =$D46/12 -> 1217
A47: Assistant Logistique / SAV (embauche CDI, 2 000€ net) | C47: Salaire | D47: 34000 | E47: Mensuel | F47: Tous les mois | G47: =$D47/12 -> 2833.3333 | H47: =$D47/12 -> 2833.3333 | I47: =$D47/12 -> 2833.3333 | J47: =$D47/12 -> 2833.3333 | K47: =$D47/12 -> 2833.3333 | L47: =$D47/12 -> 2833.3333 | M47: =$D47/12 -> 2833.3333 | N47: =$D47/12 -> 2833.3333 | ... R47: =$D47/12 -> 2833.3333
A48: Budget Marketing & Salons | C48: Marketing | D48: 50000 | E48: Mensuel | F48: Tous les mois | G48: =$D48/12 -> 4166.6667 | H48: =$D48/12 -> 4166.6667 | I48: =$D48/12 -> 4166.6667 | J48: =$D48/12 -> 4166.6667 | K48: =$D48/12 -> 4166.6667 | L48: =$D48/12 -> 4166.6667 | M48: =$D48/12 -> 4166.6667 | N48: =$D48/12 -> 4166.6667 | ... R48: =$D48/12 -> 4166.6667
...

Sheet Charges Variables
A1: CHARGES VARIABLES - PLUME PARAGLIDERS
A2: Charges liées au chiffre d'affaires
A4: CHARGES VARIABLES
A5: Poste | B5: Base de calcul | C5: Pourcentage
A7: Stock ( 66% aile stock / 33% aile démo ) | B7: Nb voiles vendues (forecast) par an | C7: 0.25
A8: Assurance | B8: % du chiffre d'affaire | C8: 0.008
A12: Transporteur
A13: Transport Thaïlande → Europe | B13: Par aile | C13: 40.57
A14: Transport stock → Europe | B14: Par aile | C14: 18.88
A16: Stockage
A17: Stockage | B17: Par aile | C17: 6.47
A19: Taxe douanière
A20: Frais de douane | B20: Prix usine | C20: 0.027
A21: Frais de dédouanement | B21: Prix usine | C21: 0.02
A23: Frais de paiement
A24: Stripe | C24: 0.015
A25: Briddge | C25: 0.011
A27: Marge des écoles partenaires
A28: marge ecole partenaire | C28: 0.19

Sheet Emprunt Bancaire
A1: EMPRUNT BANCAIRE - PLUME PARAGLIDERS
A3: CARACTÉRISTIQUES DU PRÊT
A4: Montant de l'emprunt | B4: 189000
A5: Durée | B5: 4 | C5: ans
A6: Taux d'intérêt | B6: 0.045
A7: Taux d'assurance | B7: 0.0036
A9: ÉCHÉANCIER DE REMBOURSEMENT
A10: Période | B10: Prêt Annuel (€) | C10: Assurance Annuelle (€) | D10: Total Annuel (€)
A11: Mois 1 - 48 | B11: =SUM('Emprunt Mensualité'!E27:F27) -> 51718.31 | C11: ='Emprunt Mensualité'!G27 -> 680.4 | D11: =B11+C11 -> 52398.71
A13: SYNTHÈSE SUR 4 ANS
A14: Mensualité totale | B14: =B27 -> 4367
A15: Coût total du crédit | B15: ='Emprunt Mensualité'!H63 -> 209594.88
A16: dont Intérêts | B16: ='Emprunt Mensualité'!F63 -> 17873.24
A17: dont Assurance | B17: ='Emprunt Mensualité'!G63 -> 2721.6
A19: IMPACT ANNUEL SUR TRÉSORERIE
A20: Charge annuelle de remboursement | B20: =D11 -> 52398.71
A24: DÉTAIL MENSUALITÉ CORRIGÉ
A25: Mensualité prêt (capital + intérêts) | B25: 4310
A26: Assurance mensuelle | B26: =ROUND(B4*B7/12,0) -> 57
A27: TOTAL MENSUALITÉ | B27: =B25+B26 -> 4367
A30: INTÉRÊTS ANNUELS (pour Compte de Résultat)
A31: Année | B31: Intérêts | C31: Assurance | D31: Total charges fin.
A32: 2026 | B32: 5289.03 | C32: 453.6 | D32: 5742.63
A33: 2027 | B33: 6261.51 | C33: 680.4 | D33: 6941.91
A34: 2028 | B34: 4173.24 | C34: 680.4 | D34: 4853.64
A35: 2029 | B35: 1989.02 | C35: 680.4 | D35: 2669.42
A36: 2030 | B36: 160.42 | C36: 226.8 | D36: 387.22
A37: Total intérêts | B37: =SUM(B32:B36) -> 17873.22 | C37: =SUM(C32:C36) -> 2721.6 | D37: =SUM(D32:D36) -> 20594.82
A38: Note: Seuls les intérêts sont des charges dans le Compte de Résultat.
A39: Le remboursement du capital reste dans le Plan de Trésorerie.
A42: ━━━━━━━━━━━━━━━━━━━━━━━━━━━━━━━━━━━━━━━━━━━━━━━━━━━━━━━━━━━━━━━━
A43: TABLEAU D'AMORTISSEMENT - CAPITAL RESTANT DÛ (CRD)
A44: Fin d'année | B44: Capital remboursé | C44: Intérêts payés | D44: CRD début période
A45: 2025
A46: 2026 (déblocage Mai) | B46: 29190 | C46: 5289 | D46: 189000
A47: 2027 | B47: 45457 | C47: 6262 | D47: 159810
A48: 2028 | B48: 47545 | C48: 4173 | D48: 114353
A49: 2029 | B49: 49729 | C49: 1989 | D49: 66808
A50: 2030 | B50: 17079 | C50: 160 | D50: 17079
A51: TOTAL | B51: 189000 | C51: 17873
...

Sheet Emprunt Mensualité
A1: TABLEAU DES MENSUALITÉS - PLUME PARAGLIDERS
A2: Emprunt : 189 000 € | Taux : 4.50% | Durée : 48 mois | Début : Mai 2026
A4: N° | B4: Mois | C4: Année | D4: CRD début | E4: Capital | F4: Intérêts | G4: Assurance | H4: Mensualité totale | I4: CRD fin
A5: 1 | B5: Mai | C5: 2026 | D5: 189000 | E5: 3601.11 | F5: 708.75 | G5: 56.7 | H5: 4366.56 | I5: 185398.89
A6: 2 | B6: Juin | C6: 2026 | D6: 185398.89 | E6: 3614.61 | F6: 695.25 | G6: 56.7 | H6: 4366.56 | I6: 181784.28
A7: 3 | B7: Juillet | C7: 2026 | D7: 181784.28 | E7: 3628.17 | F7: 681.69 | G7: 56.7 | H7: 4366.56 | I7: 178156.11
A8: 4 | B8: Août | C8: 2026 | D8: 178156.11 | E8: 3641.77 | F8: 668.09 | G8: 56.7 | H8: 4366.56 | I8: 174514.34
A9: 5 | B9: Septembre | C9: 2026 | D9: 174514.34 | E9: 3655.43 | F9: 654.43 | G9: 56.7 | H9: 4366.56 | I9: 170858.91
A10: 6 | B10: Octobre | C10: 2026 | D10: 170858.91 | E10: 3669.14 | F10: 640.72 | G10: 56.7 | H10: 4366.56 | I10: 167189.77
A11: 7 | B11: Novembre | C11: 2026 | D11: 167189.77 | E11: 3682.9 | F11: 626.96 | G11: 56.7 | H11: 4366.56 | I11: 163506.87
A12: 8 | B12: Décembre | C12: 2026 | D12: 163506.87 | E12: 3696.71 | F12: 613.15 | G12: 56.7 | H12: 4366.56 | I12: 159810.16
B13: Sous-total 2026 | E13: =SUM(E5:E12) -> 29189.84 | F13: =SUM(F5:F12) -> 5289.04 | G13: =SUM(G5:G12) -> 453.6 | H13: =SUM(H5:H12) -> 34932.48
A15: 9 | B15: Janvier | C15: 2027 | D15: 159810.16 | E15: 3710.57 | F15: 599.29 | G15: 56.7 | H15: 4366.56 | I15: 156099.59
A16: 10 | B16: Février | C16: 2027 | D16: 156099.59 | E16: 3724.49 | F16: 585.37 | G16: 56.7 | H16: 4366.56 | I16: 152375.11
A17: 11 | B17: Mars | C17: 2027 | D17: 152375.11 | E17: 3738.45 | F17: 571.41 | G17: 56.7 | H17: 4366.56 | I17: 148636.66
A18: 12 | B18: Avril | C18: 2027 | D18: 148636.66 | E18: 3752.47 | F18: 557.39 | G18: 56.7 | H18: 4366.56 | I18: 144884.18
A19: 13 | B19: Mai | C19: 2027 | D19: 144884.18 | E19: 3766.54 | F19: 543.32 | G19: 56.7 | H19: 4366.56 | I19: 141117.64
A20: 14 | B20: Juin | C20: 2027 | D20: 141117.64 | E20: 3780.67 | F20: 529.19 | G20: 56.7 | H20: 4366.56 | I20: 137336.97
A21: 15 | B21: Juillet | C21: 2027 | D21: 137336.97 | E21: 3794.85 | F21: 515.01 | G21: 56.7 | H21: 4366.56 | I21: 133542.13
A22: 16 | B22: Août | C22: 2027 | D22: 133542.13 | E22: 3809.08 | F22: 500.78 | G22: 56.7 | H22: 4366.56 | I22: 129733.05
A23: 17 | B23: Septembre | C23: 2027 | D23: 129733.05 | E23: 3823.36 | F23: 486.5 | G23: 56.7 | H23: 4366.56 | I23: 125909.69
A24: 18 | B24: Octobre | C24: 2027 | D24: 125909.69 | E24: 3837.7 | F24: 472.16 | G24: 56.7 | H24: 4366.56 | I24: 122071.99
A25: 19 | B25: Novembre | C25: 2027 | D25: 122071.99 | E25: 3852.09 | F25: 457.77 | G25: 56.7 | H25: 4366.56 | I25: 118219.91
A26: 20 | B26: Décembre | C26: 2027 | D26: 118219.91 | E26: 3866.53 | F26: 443.32 | G26: 56.7 | H26: 4366.56 | I26: 114353.37
B27: Sous-total 2027 | E27: =SUM(E15:E26) -> 45456.8 | F27: =SUM(F15:F26) -> 6261.51 | G27: =SUM(G15:G26) -> 680.4 | H27: =SUM(H15:H26) -> 52398.72 | J27: =SUM(E27:F27) -> 51718.31
A29: 21 | B29: Janvier | C29: 2028 | D29: 114353.37 | E29: 3881.03 | F29: 428.83 | G29: 56.7 | H29: 4366.56 | I29: 110472.34
A30: 22 | B30: Février | C30: 2028 | D30: 110472.34 | E30: 3895.59 | F30: 414.27 | G30: 56.7 | H30: 4366.56 | I30: 106576.75
A31: 23 | B31: Mars | C31: 2028 | D31: 106576.75 | E31: 3910.2 | F31: 399.66 | G31: 56.7 | H31: 4366.56 | I31: 102666.55
A32: 24 | B32: Avril | C32: 2028 | D32: 102666.55 | E32: 3924.86 | F32: 385 | G32: 56.7 | H32: 4366.56 | I32: 98741.69
A33: 25 | B33: Mai | C33: 2028 | D33: 98741.69 | E33: 3939.58 | F33: 370.28 | G33: 56.7 | H33: 4366.56 | I33: 94802.12
A34: 26 | B34: Juin | C34: 2028 | D34: 94802.12 | E34: 3954.35 | F34: 355.51 | G34: 56.7 | H34: 4366.56 | I34: 90847.77
A35: 27 | B35: Juillet | C35: 2028 | D35: 90847.77 | E35: 3969.18 | F35: 340.68 | G35: 56.7 | H35: 4366.56 | I35: 86878.59
A36: 28 | B36: Août | C36: 2028 | D36: 86878.59 | E36: 3984.06 | F36: 325.79 | G36: 56.7 | H36: 4366.56 | I36: 82894.52
A37: 29 | B37: Septembre | C37: 2028 | D37: 82894.52 | E37: 3999 | F37: 310.85 | G37: 56.7 | H37: 4366.56 | I37: 78895.52
A38: 30 | B38: Octobre | C38: 2028 | D38: 78895.52 | E38: 4014 | F38: 295.86 | G38: 56.7 | H38: 4366.56 | I38: 74881.52
A39: 31 | B39: Novembre | C39: 2028 | D39: 74881.52 | E39: 4029.05 | F39: 280.81 | G39: 56.7 | H39: 4366.56 | I39: 70852.46
A40: 32 | B40: Décembre | C40: 2028 | D40: 70852.46 | E40: 4044.16 | F40: 265.7 | G40: 56.7 | H40: 4366.56 | I40: 66808.3
B41: Sous-total 2028 | E41: =SUM(E29:E40) -> 47545.06 | F41: =SUM(F29:F40) -> 4173.24 | G41: =SUM(G29:G40) -> 680.4 | H41: =SUM(H29:H40) -> 52398.72
A43: 33 | B43: Janvier | C43: 2029 | D43: 66808.3 | E43: 4059.33 | F43: 250.53 | G43: 56.7 | H43: 4366.56 | I43: 62748.97
A44: 34 | B44: Février | C44: 2029 | D44: 62748.97 | E44: 4074.55 | F44: 235.31 | G44: 56.7 | H44: 4366.56 | I44: 58674.42
...

Sheet AFFECTATION EMPRUNT 
A1: 🏦 AFFECTATION DE L'EMPRUNT BANCAIRE — 189 000 €
A2: Emprunt Banque Populaire • 4 ans • Taux 4,5% • Échéance mensuelle 4 367 €
A4: Poste de financement | B4: Montant (€) | C4: % Emprunt | D4: Détail / Justification
A5: Homologation EN (pré-séries + tests labo) | B5: 35000 | C5: =B5/189000 -> 0.18518519 | D5: Pré-séries 10 ailes × 2 modèles + tests Air Turquoise. Obligatoire pour commercialiser (norme EN 926).
A6: Stock de lancement (ailes certifiées) | B6: 110000 | C6: =B6/189000 -> 0.58201058 | D6: ~105 ailes × coût de revient 1 049€. Actif physique tangible, stocké en France, valeur de revente > coût.
A7: Fonds de roulement (charges fixes 3 mois) | B7: 30000 | C7: =B7/189000 -> 0.15873016 | D7: Couverture charges fixes incompressibles avant montée en CA (salaires, loyers, assurances).
A8: Marge de sécurité | B8: 14000 | C8: =B8/189000 -> 0.074074074 | D8: Buffer 7% pour aléas logistiques, surcoûts qualité, ou retard de livraison usine.
A9: TOTAL EMPRUNT | B9: =SUM(B5:B8) -> 189000 | C9: =SUM(C5:C8) -> 1
A12: 📝 Les montants ci-dessus sont indicatifs. L'affectation réelle sera ajustée selon le calendrier de déblocage (mai 2026) et l'avancement des homologations EN.
A14: 📦 58% de l'emprunt finance du stock physique (ailes certifiées EN, stockées en France). En cas de défaillance, ces actifs conservent une valeur de revente estimée à 60-80% du coût d'acquisition.

Sheet Marges Produits
A1: MARGES PRODUITS - PLUME PARAGLIDERS
A3: 1. VENTE SCHOOL PACK (Vente directe écoles)
A4: Paiement immédiat via site PLUME
A5: Modèle | B5: A+ Classic
A6: Prix de vente TTC | B6: 2155
A7: Prix de vente HT | B7: =B6/1.2 -> 1795.8333
A8: Marge Partenaire | B8: 0
A10: Prix usine (aile + bags + goodies) | B10: =838+150 -> 988
A11: Transports Asie - europe | B11: ='Charges Variables'!C13 -> 40.57
A12: stockage | B12: ='Charges Variables'!C17 -> 6.47
A13: Transport Stock Europe | B13: ='Charges Variables'!C14 -> 18.88
A14: Frais de douane (2,7%) | B14: =ROUND(B10*'Charges Variables'!C20,2) -> 26.68
A15: Frais de dédouanement (2%) | B15: =ROUND(B10*'Charges Variables'!C21,2) -> 19.76
A16: Total des couts de reviens | B16: =SUM(B10:B15) -> 1100.36
A17: Frais payment | B17: 0
A19: MARGE BRUTE (€) | B19: =B7-B16-B17 -> 695.47333
A20: MARGE BRUTE (%) | B20: =1/B7*B19 -> 0.38727053
A22: 2. VENTE B2B2C (Site internet avec partenaires)
A23: Marge partenaire : 19% du prix HT
A24: Modèle | B24: A+ DLS | C24: B- Ultra | D24: K2- Ultra
A25: Prix de vente TTC | B25: 3450 | C25: 4200 | D25: 2800
A26: Prix de vente HT | B26: =B25/1.2 -> 2875 | C26: =C25/1.2 -> 3500 | D26: =D25/1.2 -> 2333.3333
A30: Prix usine ( aile+sac+goodies) | B30: =838+150 -> 988 | C30: 1099 | D30: 680
A31: Transports Asie - europe | B31: ='Charges Variables'!$C$13 -> 40.57 | C31: ='Charges Variables'!$C$13 -> 40.57 | D31: ='Charges Variables'!$C$13 -> 40.57
A32: stockage | B32: ='Charges Variables'!$C$17 -> 6.47 | C32: ='Charges Variables'!$C$17 -> 6.47 | D32: ='Charges Variables'!$C$17 -> 6.47
A33: Transport Stock Europe | B33: ='Charges Variables'!$C$14 -> 18.88 | C33: ='Charges Variables'!$C$14 -> 18.88 | D33: ='Charges Variables'!$C$14 -> 18.88
A34: Frais de douane (2,7%) | B34: =ROUND(B30*'Charges Variables'!$C$20,2) -> 26.68 | C34: =ROUND(C30*'Charges Variables'!$C$20,2) -> 29.67 | D34: =ROUND(D30*'Charges Variables'!$C$20,2) -> 18.36
A35: Frais de dédouanement (2%) | B35: =ROUND(B30*'Charges Variables'!$C$21,2) -> 19.76 | C35: =ROUND(C30*'Charges Variables'!$C$21,2) -> 21.98 | D35: =ROUND(D30*'Charges Variables'!$C$21,2) -> 13.6
A36: Total des couts de reviens | B36: =SUM(B30:B35) -> 1100.36 | C36: =SUM(C30:C35) -> 1216.57 | D36: =SUM(D30:D35) -> 777.88
A37: Frais payment | B37: =0.015*B25 -> 51.75 | C37: =0.015*C25 -> 63 | D37: =0.015*D25 -> 42
A38: Marge Partenaire (19%) | B38: =B26*'Charges Variables'!$C$28 -> 546.25 | C38: =C26*'Charges Variables'!$C$28 -> 665 | D38: =D26*'Charges Variables'!$C$28 -> 443.33333
A39: MARGE BRUTE (€) | B39: =B26-B38-B36-B37 -> 1176.64 | C39: =C26-C38-C36-C37 -> 1555.43 | D39: =D26-D38-D36-D37 -> 1070.12
A40: MARGE BRUTE (%) | B40: =1/B26*B39 -> 0.40926609 | C40: =1/C26*C39 -> 0.44440857 | D40: =1/D26*D39 -> 0.45862286
A42: 3. Hypothèse 1 de la répartition des ventes
A43: Canal de vente | B43: Produit | C43: Prix HT | D43: Marge € | E43: Cout de reviens | F43: Proportions des ventes | G43: Marge Brute
A44: School Pack | B44: A+ Classic | C44: =B7 -> 1795.8333 | D44: =B19 -> 695.47333 | E44: =B16 -> 1100.36 | F44: 0.3 | G44: =B20 -> 0.38727053
A45: B2B2C | B45: A+ Classic | C45: =B26 -> 2875 | D45: =B39 -> 1176.64 | E45: =B36 -> 1100.36 | F45: 0.2 | G45: =B40 -> 0.40926609
A46: B2B2C | B46: B- Ultra | C46: =C26 -> 3500 | D46: =C39 -> 1555.43 | E46: =C36 -> 1216.57 | F46: 0.25 | G46: =C40 -> 0.44440857
A47: B2B2C | B47: K2- Ultra | C47: =D26 -> 2333.3333 | D47: =D39 -> 1070.12 | E47: =D36 -> 777.88 | F47: 0.25 | G47: =D40 -> 0.45862286
A49: Hypothese 1: prix moyen / produit | C49: =(C44*F44)+(C45*F45)+(C46*F46)+(C47*F47) -> 2572.0833 | D49: =(D44*F44)+(D45*F45)+(D46*F46)+(D47*F47) -> 1100.3575 | E49: =(E44*F44)+(E45*F45)+(E46*F46)+(E47*F47) -> 1048.7925 | G49: =1/C49*D49 -> 0.42780787
...

Sheet Financement
A1: FINANCEMENT & MONTAGE SOCIÉTÉ - PLUME PARAGLIDERS
A3: MONTAGE SOCIÉTÉ - CAPITAL SOCIAL
A4: Associé / Source | B4: Apport total | C4: Capital social | D4: Part capital
A5: Jean-Baptiste Chandelier | B5: 104000 | C5: 55000 | D5: 0.55
A6: Thomas Pierre-Bes | B6: 85000 | C6: 45000 | D6: 0.45
A7: Sous-total Associés | B7: =SUM(B5:B6) -> 189000 | C7: =SUM(C5:C6) -> 100000 | D7: =SUM(D5:D6) -> 1
A8: correspond aux comptes courants d'associés (89k€).
A11: FINANCEMENTS EXTERNES
A12: Source | B12: Montant | C12: Type | D12: Année
A13: Banque Populaire - Emprunt 1/1 | B13: ='Emprunt Bancaire'!B4 -> 189000 | C13: Emprunt 4 ans | D13: 2026
A14: Sous-total Financements Externes | B14: =B13 -> 189000
A17: APPORT COMPLÉMENTAIRE ANNÉE 2
A18: Source | B18: Montant | C18: Objet | D18: Année
A19: Avoir EURL JB Chandelier | B19: 50000 | C19: Marketing & Tests | D19: 2027
A20: Note: Prestation externe pour fonds de roulement
A22: RÉCAPITULATIF FINANCEMENT TOTAL
A23: Apports associés (Année 1) | B23: =B7 -> 189000
A24: Financements externes (Année 1) | B24: =B14 -> 189000
A25: Avoir EURL JB Chandelier (Année 2) | B25: =B19 -> 50000
A26: TOTAL FINANCEMENT | B26: =SUM(B23:B25) -> 428000
A28: FLUX DE FINANCEMENT PAR ANNÉE
A29: Année | B29: Entrées | C29: Détail
A30: 2025 | B30: 0
A31: 2026 | B31: =B23+B24 -> 378000 | C31: Associés + Emprunt
A32: 2027 | B32: =B25 -> 50000 | C32: Avoir EURL JB Chandelier
A33: 2028+ | B33: 0 | C33: -
A38: 📅 CALENDRIER DE DÉBLOCAGE (Création 18/12/2025)
A39: Decembre 2025 | B39: Capital social | C39: 100000
A40: Janvier 2026 | B40: Comptes courants associés | C40: 89000
A41: Mai 2026 | B41: Emprunt Banque Populaire | C41: 189000
A42: Mars 2027 | B42: Avoir EURL JB | C42: 50000
A47: Sécurité financière des fondateurs
A48: Les fondateurs disposent de revenus complémentaires qui assurent leur stabilité personnelle pendant la phase de lancement :
A50: JB Chandelier — revenus via son EURL Chandelier (prestations vidéo, droits d'image, partenariats Salewa, Blacksheep, Serre Chevalier), revenus patrimoniaux personnels, brevets d'État parapente/ski.
A52: Thomas Pierre-Bes — auto-entrepreneur (R&D parapente, impression 3D, prestations vidéo), brevets d'État kitesurf.
A54: La rémunération via Plume Paragliders est volontairement contenue pour préserver la trésorerie. Les comptes courants d'associés (89 000 €) seront remboursés une fois la rentabilité atteinte, avec revalorisation progressive des rémunérations à partir du seuil de ~180 ailes/an.
A56: Le capital de 100 000 € est dimensionné au juste besoin de la phase de lancement. JB Chandelier dispose par ailleurs d'un patrimoine personnel significatif, mobilisable en renfort si nécessaire pour accompagner l'atteinte de la rentabilité.

Sheet Scénarios
A1: SCÉNARIOS DE VENTES - PLUME PARAGLIDERS
A3: Répartition des ventes
A4: {='Marges Produits'!A43:F43} -> Canal de vente | B4: Produit | C4: Prix HT | D4: Marge € | E4: Cout de reviens | F4: Proportions des ventes
A5: {='Marges Produits'!A44:F44} -> School Pack | B5: A+ Classic | C5: 1795.8333 | D5: 695.47333 | E5: 1100.36 | F5: 0.3
A6: {='Marges Produits'!A45:F45} -> B2B2C | B6: A+ Classic | C6: 2875 | D6: 1176.64 | E6: 1100.36 | F6: 0.2
A7: {='Marges Produits'!A46:F46} -> B2B2C | B7: B- Ultra | C7: 3500 | D7: 1555.43 | E7: 1216.57 | F7: 0.25
A8: {='Marges Produits'!A47:F47} -> B2B2C | B8: K2- Ultra | C8: 2333.3333 | D8: 1070.12 | E8: 777.88 | F8: 0.25
A10: {='Marges Produits'!A49:E49} -> Hypothese 1: prix moyen / produit | B10: 0 | C10: 2572.0833 | D10: 1100.3575 | E10: 1048.7925
A13: VOLUMES DE VENTES (Nombre d'ailes)
A14: Année | B14: 2025 | C14: 2026 | D14: 2027 | E14: 2028 | F14: 2029 | G14: 2030 | H14: 2031
A16: 🟠 RÉALISTE | B16: 0 | C16: 75 | D16: 250 | E16: 550 | F16: 800 | G16: 1000 | H16: 1000
A17: 🔴 POINT MORT (minimum syndical) | B17: ='Analyse Point Mort'!B19 -> 0 | C17: ='Analyse Point Mort'!C19 -> 0 | D17: ='Analyse Point Mort'!D19 -> 139 | E17: ='Analyse Point Mort'!E19 -> 242 | F17: ='Analyse Point Mort'!F19 -> 242 | G17: ='Analyse Point Mort'!G19 -> 187 | H17: ='Analyse Point Mort'!H19 -> 187
A19: SCÉNARIO RÉALISTE - DÉTAIL
A20: Volume TOTAL | B20: =B16 -> 0 | C20: =C16 -> 75 | D20: =D16 -> 250 | E20: =E16 -> 550 | F20: =F16 -> 800 | G20: =G16 -> 1000 | H20: =H16 -> 1000
A21: résultat net | B21: ='Compte de Résultat'!B34 -> -8857.8558 | C21: ='Compte de Résultat'!C34 -> -128458.89 | D21: ='Compte de Résultat'!D34 -> 50265.066 | E21: ='Compte de Résultat'!E34 -> 382760.59 | F21: ='Compte de Résultat'!F34 -> 518386.01 | G21: ='Compte de Résultat'!G34 -> 690585.36 | H21: ='Compte de Résultat'!H34 -> 756513.57
A22: CA TOTAL (HT) | B22: ='Compte de Résultat'!B13 -> 0 | C22: ='Compte de Résultat'!C13 -> 192906.25 | D22: ='Compte de Résultat'!D13 -> 643020.83 | E22: ='Compte de Résultat'!E13 -> 1414645.8 | F22: ='Compte de Résultat'!F13 -> 2057666.7 | G22: ='Compte de Résultat'!G13 -> 2572083.3 | H22: ='Compte de Résultat'!H13 -> 2700687.5
A29: COMPARAISON CA TOTAL (HT)
A31: 🟠 CA Réaliste | B31: =B22 -> 0 | C31: =C22 -> 192906.25 | D31: =D22 -> 643020.83 | E31: =E22 -> 1414645.8 | F31: =F22 -> 2057666.7 | G31: =G22 -> 2572083.3 | H31: =H22 -> 2700687.5
A34: 📌 STRATÉGIE PLAFOND 1000 AILES
A35: Au-delà de 1000 ailes/an, l'objectif n'est plus d'augmenter le volume mais la marge.
A36: Stratégie : produire légèrement moins que la demande pour valoriser le produit et augmenter le prix.
A37: Cette limitation volontaire de la production permet de renforcer le positionnement premium.

Sheet Plan Trésorerie Mensuel
A1: PLAN DE TRÉSORERIE MENSUEL - PLUME PARAGLIDERS
A2: Création : 18 décembre 2025 • Délais de financement réalistes
A4: 📅 ANNÉE 2026 : LANCEMENT
B5: Déc 25 | C5: Jan | D5: Fév | E5: Mar | F5: Avr | G5: Mai | H5: Juin | I5: Juil | J5: Août | K5: Sept | L5: Oct | M5: Nov | N5: Déc | O5: TOTAL
A6: ENTRÉES
A7: Capital social | B7: =Dashboard!B9 -> 100000 | C7: 0 | D7: 0 | E7: 0 | F7: 0 | G7: 0 | H7: 0 | I7: 0 | J7: 0 | K7: 0 | L7: 0 | M7: 0 | N7: 0 | O7: =SUM(B7:N7) -> 100000
A8: Comptes courants associés | B8: 0 | C8: 89000 | D8: 0 | E8: 0 | F8: 0 | G8: 0 | H8: 0 | I8: 0 | J8: 0 | K8: 0 | L8: 0 | M8: 0 | N8: 0 | O8: =SUM(B8:N8) -> 89000
A9: Emprunt bancaire | B9: 0 | C9: 0 | D9: 0 | F9: 0 | G9: ='Emprunt Bancaire'!B4 -> 189000 | H9: 0 | I9: 0 | J9: 0 | K9: 0 | L9: 0 | M9: 0 | N9: 0 | O9: =SUM(B9:N9) -> 189000
O10: =SUM(O8:O9) -> 278000
A12: CA Ventes (HT) | B12: 0 | C12: =C35*'Marges Produits'!$C$49 -> 0 | D12: =D35*'Marges Produits'!$C$49 -> 0 | E12: =E35*'Marges Produits'!$C$49 -> 0 | F12: =F35*'Marges Produits'!$C$49 -> 12860.417 | G12: =G35*'Marges Produits'!$C$49 -> 18004.583 | H12: =H35*'Marges Produits'!$C$49 -> 23148.75 | I12: =I35*'Marges Produits'!$C$49 -> 30865 | J12: =J35*'Marges Produits'!$C$49 -> 30865 | ... N12: =N35*'Marges Produits'!$C$49 -> 12860.417 | O12: =SUM(B12:N12) -> 192906.25
A13: Total entrées | B13: =SUM(B7:B12) -> 100000 | C13: =SUM(C7:C12) -> 89000 | D13: =SUM(D7:D12) -> 0 | E13: =SUM(E7:E12) -> 0 | F13: =SUM(F7:F12) -> 12860.417 | G13: =SUM(G7:G12) -> 207004.58 | H13: =SUM(H7:H12) -> 23148.75 | I13: =SUM(I7:I12) -> 30865 | ... N13: =SUM(N7:N12) -> 12860.417 | O13: =SUM(B13:N13) -> 570906.25
A15: SORTIES
A16: Frais création | B16: ='Frais de lancement'!B9 -> 3803 | C16: 0 | D16: 0 | E16: 0 | F16: 0 | G16: 0 | H16: 0 | I16: 0 | J16: 0 | K16: 0 | L16: 0 | M16: 0 | N16: 0 | O16: =SUM(B16:N16) -> 3803
A17: Frais prototype | B17: 0 | C17: ='Charges Fixes Plume'!G34 -> 10000 | D17: ='Charges Fixes Plume'!H34 -> 0 | E17: ='Charges Fixes Plume'!I34 -> 0 | F17: ='Charges Fixes Plume'!J34 -> 0 | G17: ='Charges Fixes Plume'!K34 -> 2517.102 | H17: ='Charges Fixes Plume'!L34 -> 2517.102 | I17: ='Charges Fixes Plume'!M34 -> 2517.102 | J17: ='Charges Fixes Plume'!N34 -> 2517.102 | ... N17: ='Charges Fixes Plume'!R34 -> 2517.102 | O17: =SUM(B17:N17) -> 30136.816
A18: Veille concurrentielle | B18: 0 | C18: 2500 | D18: 0 | E18: 0 | F18: 0 | G18: 0 | H18: 0 | I18: 2500 | J18: 0 | K18: 0 | L18: 0 | M18: 0 | N18: 0 | O18: =SUM(B18:N18) -> 5000
A19: Masse salariale | B19: ='Charges Fixes Plume'!R$13/2 -> 2170.8333 | C19: ='Charges Fixes Plume'!G13 -> 10907.667 | D19: ='Charges Fixes Plume'!H13 -> 6341.6667 | E19: ='Charges Fixes Plume'!I13 -> 10907.667 | F19: ='Charges Fixes Plume'!J13 -> 4341.6667 | G19: ='Charges Fixes Plume'!K13 -> 8907.6667 | H19: ='Charges Fixes Plume'!L13 -> 4341.6667 | I19: ='Charges Fixes Plume'!M13 -> 7907.6667 | J19: ='Charges Fixes Plume'!N13 -> 3341.6667 | ... N19: ='Charges Fixes Plume'!R13 -> 4341.6667 | O19: =SUM(B19:N19) -> 85666.833
A20: CHARGES DE CROISSANCE ( si n-1 = + 500ailes)
A21: Charges exploitation | B21: ='Charges Fixes Plume'!R$29/2 -> 1728.65 | C21: ='Charges Fixes Plume'!G29 -> 9057.3 | D21: ='Charges Fixes Plume'!H29 -> 3977.3 | E21: ='Charges Fixes Plume'!I29 -> 3407.3 | F21: ='Charges Fixes Plume'!J29 -> 4407.3 | G21: ='Charges Fixes Plume'!K29 -> 3407.3 | H21: ='Charges Fixes Plume'!L29 -> 3407.3 | I21: ='Charges Fixes Plume'!M29 -> 4407.3 | J21: ='Charges Fixes Plume'!N29 -> 3407.3 | ... N21: ='Charges Fixes Plume'!R29 -> 3457.3 | O21: =SUM(B21:N21) -> 51886.25
A22: Pré-série homologation (10) | B22: 0 | C22: 0 | D22: 0 | E22: ='Charges Fixes Plume'!C36*4 -> 5034.204 | F22: 0 | G22: =4*'Charges Fixes Plume'!$C$36 -> 5034.204 | H22: 0 | I22: 0 | K22: 0 | L22: 0 | M22: 0 | N22: 0 | O22: =SUM(B22:N22) -> 10068.408
A23: Tests homologation EN | B23: 0 | C23: 0 | D23: 0 | F23: 11172 | G23: 0 | H23: ='Charges Fixes Plume'!C37 -> 13669 | I23: 0 | K23: 0 | L23: 0 | M23: 0 | N23: 0 | O23: =SUM(B23:N23) -> 24841
A24: Production stock parapente | B24: 0 | C24: =C34*'Marges Produits'!$E$49 -> 0 | D24: =D34*'Marges Produits'!$E$49 -> 0 | E24: =E34*'Marges Produits'!$E$49 -> 0 | F24: =F34*'Marges Produits'!$E$49 -> 10487.925 | G24: =G34*'Marges Produits'!$E$49 -> 20975.85 | H24: =H34*'Marges Produits'!$E$49 -> 20975.85 | I24: =I34*'Marges Produits'!$E$49 -> 18878.265 | J24: =J34*'Marges Produits'!$E$49 -> 10487.925 | ... N24: =N34*'Marges Produits'!$E$49 -> 0 | O24: =SUM(B24:N24) -> 94391.325
A25: Remboursement emprunt | B25: 0 | C25: 0 | D25: 0 | E25: 0 | G25: ='Emprunt Bancaire'!$B$27 -> 4367 | H25: ='Emprunt Bancaire'!$B$27 -> 4367 | I25: ='Emprunt Bancaire'!$B$27 -> 4367 | J25: ='Emprunt Bancaire'!$B$27 -> 4367 | K25: ='Emprunt Bancaire'!$B$27 -> 4367 | L25: ='Emprunt Bancaire'!$B$27 -> 4367 | M25: ='Emprunt Bancaire'!$B$27 -> 4367 | N25: ='Emprunt Bancaire'!$B$27 -> 4367 | O25: =SUM(B25:N25) -> 34936
A26: Assurance RC (0.8% CA) | B26: =B12*0.008 -> 0 | C26: =C12*0.008 -> 0 | D26: =D12*0.008 -> 0 | E26: =E12*0.008 -> 0 | F26: =F12*0.008 -> 102.88333 | G26: =G12*0.008 -> 144.03667 | H26: =H12*0.008 -> 185.19 | I26: =I12*0.008 -> 246.92 | ... N26: =N12*0.008 -> 102.88333 | O26: =SUM(B26:N26) -> 1543.25
A27: imprévue: 15% de total sortie | B27: {=SUM(B16:B26*0.15)} -> 1155.3725 | C27: {=SUM(C16:C26*0.15)} -> 4869.745 | D27: {=SUM(D16:D26*0.15)} -> 1547.845 | E27: {=SUM(E16:E26*0.15)} -> 2902.3756 | F27: {=SUM(F16:F26*0.15)} -> 4576.7662 | G27: {=SUM(G16:G26*0.15)} -> 6802.9739 | H27: {=SUM(H16:H26*0.15)} -> 7419.4663 | I27: {=SUM(I16:I26*0.15)} -> 6123.638 | ... N27: {=SUM(N16:N26*0.15)} -> 2217.8928 | O27: =SUM(B27:N27) -> 51340.932
A28: Total sorties | B28: =SUM(B16:B27) -> 8857.8558 | C28: =SUM(C16:C27) -> 37334.712 | D28: =SUM(D16:D27) -> 11866.812 | E28: =SUM(E16:E27) -> 22251.546 | F28: =SUM(F16:F27) -> 35088.541 | G28: =SUM(G16:G27) -> 52156.133 | H28: =SUM(H16:H27) -> 56882.575 | I28: =SUM(I16:I27) -> 46947.892 | ... N28: =SUM(N16:N27) -> 17003.845 | O28: =SUM(B28:N28) -> 393613.81
A30: FLUX MENSUEL | B30: =B13-B28 -> 91142.144 | C30: =C13-C28 -> 51665.288 | D30: =D13-D28 -> -11866.812 | E30: =E13-E28 -> -22251.546 | F30: =F13-F28 -> -22228.125 | G30: =G13-G28 -> 154848.45 | H30: =H13-H28 -> -33733.825 | I30: =I13-I28 -> -16082.892 | ... N30: =N13-N28 -> -4143.4281 | O30: =SUM(C30:N30) -> 86150.291
A31: TRÉSORERIE CUMULÉE | B31: =B30 -> 91142.144 | C31: =B31+C30 -> 142807.43 | D31: =C31+D30 -> 130940.62 | E31: =D31+E30 -> 108689.07 | F31: =E31+F30 -> 86460.95 | G31: =F31+G30 -> 241309.4 | H31: =G31+H30 -> 207575.58 | I31: =H31+I30 -> 191492.68 | J31: =I31+J30 -> 194334.58 | ... N31: =M31+N30 -> 177292.44
A33: 📦 Volumes
A34: Production (nb ailes) | B34: 0 | C34: 0 | D34: 0 | E34: 0 | F34: 10 | G34: 20 | H34: 20 | I34: 18 | J34: 10 | K34: 7 | L34: 5 | M34: 0 | N34: 0 | O34: =SUM(B34:N34) -> 90
A35: Ventes (nb ailes) | B35: 0 | C35: 0 | D35: 0 | E35: 0 | F35: 5 | G35: 7 | H35: 9 | I35: 12 | J35: 12 | K35: 10 | L35: 10 | M35: 5 | N35: 5 | O35: =SUM(B35:N35) -> 75
A36: Stock fin de mois | B36: 0 | C36: =(C34+B36)-C35 -> 0 | D36: =(D34+C36)-D35 -> 0 | E36: =(E34+D36)-E35 -> 0 | F36: =(F34+E36)-F35 -> 5 | G36: =(G34+F36)-G35 -> 18 | H36: =(H34+G36)-H35 -> 29 | I36: =(I34+H36)-I35 -> 35 | J36: =(J34+I36)-J35 -> 33 | ... N36: =(N34+M36)-N35 -> 15
A39: 📅 ANNÉE 2027 : CROISSANCE | B39: 📅 ANNÉE 2027 : CROISSANCE | N39: 📅 ANNÉE 2028 : CROISSANCE | Z39: 📅 ANNÉE 2029 : CROISSANCE | AL39: 📅 ANNÉE 2030 : CROISSANCE | AX39: 📅 ANNÉE 2031 : CROISSANCE
B40: Jan | C40: Fév | D40: Mar | E40: Avr | F40: Mai | G40: Juin | H40: Juil | I40: Août | J40: Sept | K40: Oct | L40: Nov | M40: Déc | N40: Jan | O40: Fév | P40: Mar | Q40: Avr | R40: Mai | S40: Juin | T40: Juil | U40: Août | V40: Sept | W40: Oct | X40: Nov | Y40: Déc | Z40: Jan | AA40: Fév | AB40: Mar | AC40: Avr | AD40: Mai | AE40: Juin | AF40: Juil | AG40: Août | AH40: Sept | AI40: Oct | AJ40: Nov | AK40: Déc | AL40: Jan | AM40: Fév | AN40: Mar | AO40: Avr | AP40: Mai | AQ40: Juin | AR40: Juil | AS40: Août | AT40: Sept | AU40: Oct | AV40: Nov | AW40: Déc | AX40: Jan | AY40: Fév | AZ40: Mar | BA40: Avr | BB40: Mai | BC40: Juin | BD40: Juil | BE40: Août | BF40: Sept | BG40: Oct | BH40: Nov | BI40: Déc
A41: ENTRÉES
A42: Apport | B42: 0 | C42: 0 | D42: 50000 | E42: 0 | F42: 0 | G42: 0 | H42: 0 | I42: 0 | J42: 0 | K42: 0 | L42: 0 | M42: 0
A43: CA Ventes (HT) | B43: =B65*'Marges Produits'!$C$49 -> 12860.417 | C43: =C65*'Marges Produits'!$C$49 -> 25720.833 | D43: =D65*'Marges Produits'!$C$49 -> 38581.25 | E43: =E65*'Marges Produits'!$C$49 -> 64302.083 | F43: =F65*'Marges Produits'!$C$49 -> 90022.917 | G43: =G65*'Marges Produits'!$C$49 -> 90022.917 | H43: =H65*'Marges Produits'!$C$49 -> 90022.917 | I43: =I65*'Marges Produits'!$C$49 -> 77162.5 | ... AW43: =AW65*'Marges Produits'!$C$49 -> 97739.167 | AX43: =AX65*(('Marges Produits'!$C$51)) -> 135034.38 | AY43: =AY65*(('Marges Produits'!$C$51)) -> 151238.5 | AZ43: =AZ65*(('Marges Produits'!$C$51)) -> 218755.69 | BA43: =BA65*(('Marges Produits'!$C$51)) -> 286272.88 | BB43: =BB65*(('Marges Produits'!$C$51)) -> 337585.94 | BC43: =BC65*(('Marges Produits'!$C$51)) -> 337585.94 | BD43: =BD65*(('Marges Produits'!$C$51)) -> 337585.94 | BE43: =BE65*(('Marges Produits'!$C$51)) -> 286272.88 | ... BI43: =BI65*(('Marges Produits'!$C$51)) -> 102626.13
A44: Total entrées | B44: =SUM(B42:B43) -> 12860.417 | C44: =SUM(C42:C43) -> 25720.833 | D44: =SUM(D42:D43) -> 88581.25 | E44: =SUM(E42:E43) -> 64302.083 | F44: =SUM(F42:F43) -> 90022.917 | G44: =SUM(G42:G43) -> 90022.917 | H44: =SUM(H42:H43) -> 90022.917 | I44: =SUM(I42:I43) -> 77162.5 | ... BI44: =SUM(BI42:BI43) -> 102626.13
A46: SORTIES
