Workbook

Sheet Dashboard
B2: PLUME PARAGLIDERS
B3: Business Plan 2025-2031 • Tableau de Bord Exécutif
B6: 📊 INDICATEURS CLÉS | K6: 💼 PLAN DE FINANCEMENT
B7: 📅 CRÉATION | C7: 15 décembre 2025 | K7: JB Chandelier | L7: 104000 | M7: 55%
B8: Capital social | D8: Plan de financement | F8: Seuil rentabilité | H8: Marge nette/aile | K8: Thomas Pierre-Bes | L8: 85000 | M8: 45%
B9: =Financement!C7 -> 100000 | D9: =L12 -> 428000 | F9: ='Seuil Rentabilité'!C21 -> 187 | H9: =ROUND('Seuil Rentabilité'!B8,0)&" €" -> 1092 € | K9: Emprunt 4 ans | L9: 189000
K10: Avoir EURL JB (2027) | L10: 50000
B12: 📈 SCÉNARIOS DE VENTES (Nombre d'ailes) | K12: TOTAL | L12: =SUM(L7:L10) -> 428000
C13: 2025 | D13: 2026 | E13: 2027 | F13: 2028 | G13: 2029 | H13: 2030 | I13: 2031
B14: 🟠 Réaliste | C14: 0 | D14: 75 | E14: 250 | F14: 550 | G14: 800 | H14: 1000 | I14: 1000 | K14: 📋 CHARGES FIXES / AN
B15: 🔴 Point Mort | C15: 0 | D15: 0 | E15: 63 | F15: 372 | G15: 100 | H15: 249 | I15: 118 | K15: Masse salariale | L15: ='Charges Fixes Plume'!D13 -> 101476
K16: Investissement R&D | L16: ='Charges Fixes Plume'!D37 -> 54168.558
K17: Exploitation | L17: ='Charges Fixes Plume'!C28 -> 40114
K19: TOTAL | L19: ='Charges Fixes Plume'!D44 -> 195758.56
B20: 💰 RÉSULTATS PRÉVISIONNELS - SCÉNARIO RÉALISTE
C21: 2025 | D21: 2026 | E21: 2027 | F21: 2028 | G21: 2029 | H21: 2030 | I21: 2031 | K21: 🏦 EMPRUNT BANCAIRE
B22: Chiffre d'affaires | C22: 0 | D22: ='Plan Trésorerie Mensuel'!O12 -> 186499.99 | E22: ='Plan Trésorerie Mensuel'!M65 -> 621666.63 | F22: ='Plan Trésorerie Mensuel'!Y65 -> 1367666.6 | G22: ='Plan Trésorerie Mensuel'!AK65 -> 1989333.2 | H22: ='Plan Trésorerie Mensuel'!AW65 -> 2486666.5 | I22: ='Plan Trésorerie Mensuel'!BI65 -> 2610999.8 | K22: Montant | L22: ='Emprunt Bancaire'!B4 -> 189000
B23: bénéfice net | C23: 0 | D23: ='Compte de Résultat'!C34 -> -122170.51 | E23: ='Compte de Résultat'!D34 -> 70886.784 | F23: ='Compte de Résultat'!E34 -> 400488.99 | G23: ='Compte de Résultat'!F34 -> 675607.84 | H23: ='Compte de Résultat'!G34 -> 895848.81 | I23: ='Compte de Résultat'!H34 -> 950429.18 | K23: Durée | L23: 4 ans
B24: Trésorerie cumulée | C24: ='Compte de Résultat'!B45 -> 77342.029 | D24: ='Compte de Résultat'!C45 -> 167099.31 | E24: ='Compte de Résultat'!D45 -> 187390.56 | F24: ='Compte de Résultat'!E45 -> 561319.06 | G24: ='Compte de Résultat'!F45 -> 1202832.8 | H24: ='Compte de Résultat'!G45 -> 2205262.6 | I24: ='Compte de Résultat'!H45 -> 3436998.4 | K24: Taux | L24: ='Emprunt Bancaire'!B6 -> 0.045
K25: Échéance/an | L25: ='Emprunt Bancaire'!D11 -> 52400
K27: ✅ POINTS CLÉS
K28: ✓ Rentabilité dès 2027
K29: ✓ Seuil : 187 ailes/an
K30: ✓ Marge brute ~45%
K31: ✓ Tréso toujours positive
K32: ✓ Emprunt remboursé 2029

Sheet Frais de lancement
A1: PLUME PARAGLIDERS - CHARGES FIXES
A2: lancement
A5: 1. FRAIS DE LANCEMENT (One-shot)
A6: Poste | B6: Montant (€)
A7: Charte Graphique | B7: 500
A8: Création d'entreprise (Avocat) | B8: 3303
A9: SOUS-TOTAL LANCEMENT | B9: =SUM(B7:B8) -> 3803

Sheet Charges Fixes Plume
A1: PLUME PARAGLIDERS - CHARGES FIXES
A5: 1. MASSE SALARIALE ANNUELLE
A6: Note: Abattement ZFRR + ACRE appliqué
A7: Collaborateur | B7: Nb mois | C7: Type | D7: Charge annuelle (€)
A8: Manu Lalie | B8: 10 | C8: Prestation | D8: 10000
A9: Yann Freund | B9: 3 | C9: Prestation | D9: 6000
A10: Jean-Baptiste Chandelier | B10: 12 | C10: Salaire | D10: 21600
A11: Thomas Pierre-Bes | B11: 12 | C11: Salaire | D11: 36480
A12: Jim Nougarolles | B12: 12 | C12: Prestation | D12: 27396
A13: SOUS-TOTAL MASSE SALARIALE | D13: =SUM(D8:D12) -> 101476
A15: 2. CHARGES D'EXPLOITATION ANNUELLES (hors masse salariale)
A16: Poste | B16: Catégorie | C16: Montant (€/an)
A17: OVH Website | B17: License | C17: 50
A18: Déplacements / Nourriture / Logement | B18: Déplacement | C18: 10000
A19: Adobe | B19: Logiciel | C19: 900
A20: Dropbox | B20: License | C20: 864
A21: Loyer | B21: Frais fixe | C21: 9600
A22: Notion | B22: Gestion | C22: 570
A23: AI Assistant | B23: Logiciel | C23: 4000
A24: Art List | B24: License | C24: 480
A25: Glider Plan | B25: Logiciel | C25: 4650
A26: Investissement matériel | B26: Achat | C26: 5000
A27: Comptabilité | B27: Gestion | C27: 4000
A28: SOUS-TOTAL EXPLOITATION | C28: =SUM(C17:C27) -> 40114
A31: 3. INVESTISSEMENT R&D ANNUEL
A32: Poste | B32: Nb protos | C32: Prix unitaire (€) | D32: Coût total (€)
A33: Proto recherche | B33: 24 | C33: ='Marges Produits'!E45*1.2 -> 1118.487 | D33: =B33*C33 -> 26843.688
A34: Veille concurrentielle | B34: 2 | C34: 2500 | D34: =B34*C34 -> 5000
A35: Pré-série homologation | B35: 10 | C35: =C33 -> 1118.487 | D35: =B35*C35 -> 11184.87
A36: Homologation | B36: 2 | C36: 5570 | D36: =B36*C36 -> 11140
A37: SOUS-TOTAL R&D | D37: =SUM(D33:D36) -> 54168.558
A39: RÉCAPITULATIF GÉNÉRAL
A40: Masse salariale annuelle | B40: =D13 -> 101476 | D40: =D13 -> 101476
A41: Charges d'exploitation annuelles | B41: =C28 -> 40114 | D41: =C28 -> 40114
A42: Investissement R&D annuel | B42: =D37 -> 54168.558 | D42: =D37 -> 54168.558
A44: TOTAL CHARGES FIXES ANNÉE 1 | B44: =SUM(B40:B42) -> 195758.56 | D44: =SUM(D40:D42) -> 195758.56

Sheet Emprunt Bancaire
A1: EMPRUNT BANCAIRE - PLUME PARAGLIDERS
A3: CARACTÉRISTIQUES DU PRÊT
A4: Montant de l'emprunt | B4: 189000
A5: Durée | B5: 4 | C5: ans
A6: Taux d'intérêt | B6: 0.045
A7: Taux d'assurance | B7: 0.0036
A9: ÉCHÉANCIER DE REMBOURSEMENT
A10: Période | B10: Prêt Annuel (€) | C10: Assurance Annuelle (€) | D10: Total Annuel (€)
A11: Mois 1 - 48 | B11: 51720 | C11: 680 | D11: =B11+C11 -> 52400
A13: SYNTHÈSE SUR 4 ANS
A14: Mensualité totale | B14: 4310
A15: Coût total du crédit | B15: =B14*12*B5 -> 206880
A16: dont Intérêts | B16: =B39 -> 17873
A17: dont Assurance | B17: 2722
A19: IMPACT ANNUEL SUR TRÉSORERIE
A20: Charge annuelle de remboursement | B20: =D11 -> 52400
A24: DÉTAIL MENSUALITÉ CORRIGÉ
A25: Mensualité prêt (capital + intérêts) | B25: 4310
A26: Assurance mensuelle | B26: =ROUND(B4*B7/12,0) -> 57
A27: TOTAL MENSUALITÉ | B27: =B25+B26 -> 4367
A29: Charge annuelle totale | B29: =B27*12 -> 52404
A30: Coût total sur 4 ans | B30: =B29*B5 -> 209616
A32: INTÉRÊTS ANNUELS (pour Compte de Résultat)
A33: Année | B33: Intérêts | C33: Assurance | D33: Total charges fin.
A34: Année | B34: Intérêts | C34: Note
A35: 2026 | B35: 7602 | C35: =$B$17/4 -> 680.5 | D35: =B35+C35 -> 8282.5
A36: 2027 | B36: 5576 | C36: =$B$17/4 -> 680.5 | D36: =B36+C36 -> 6256.5
A37: 2028 | B37: 3456 | C37: =$B$17/4 -> 680.5 | D37: =B37+C37 -> 4136.5
A38: 2029 | B38: 1239 | C38: =$B$17/4 -> 680.5 | D38: =B38+C38 -> 1919.5
A39: Total intérêts | B39: =SUM(B35:B38) -> 17873 | C39: =SUM(C35:C38) -> 2722 | D39: =SUM(D35:D38) -> 20595
A41: Note: Seuls les intérêts sont des charges dans le Compte de Résultat.
A42: Le remboursement du capital reste dans le Plan de Trésorerie.
A45: ━━━━━━━━━━━━━━━━━━━━━━━━━━━━━━━━━━━━━━━━━━━━━━━━━━━━━━━━━━━━━━━━
A46: TABLEAU D'AMORTISSEMENT - CAPITAL RESTANT DÛ (CRD)
A48: Fin d'année | B48: Capital remboursé | C48: Intérêts payés | D48: CRD fin période
A49: 2025 (déblocage mars) | B49: 0 | C49: 0
A50: 2026 | B50: 44118 | C50: 7602 | D50: 189000
A51: 2027 | B51: 46142 | C51: 5576 | D51: 144882
A52: 2028 | B52: 48262 | C52: 3456 | D52: 98740
A53: 2029 | B53: 50478 | C53: 1239 | D53: 50478
...

Sheet Charges Variables
A1: CHARGES VARIABLES - PLUME PARAGLIDERS
A2: Charges liées au chiffre d'affaires
A4: CHARGES VARIABLES
A5: Poste | B5: Base de calcul | C5: Pourcentage
A6: Ré-investissement 30% du bénéfice | B6: Bénéfice | C6: 0.3
A7: Stock | B7: Nb voiles vendues (forecast) | C7: 0.5
A8: Assurance | B8: - | C8: 0.008
A10: Note: L'assurance RC Produit (0.8% du CA) est une estimation.

Sheet Marges Produits
A1: MARGES PRODUITS - PLUME PARAGLIDERS
A3: 1. VENTE SCHOOL PACK (Vente directe écoles)
A4: Paiement immédiat via site PLUME
A5: Modèle | B5: A+ Classic
A6: Prix de vente TTC | B6: 1980
A7: Prix de vente HT | B7: 1650
A8: Marge Partenaire | B8: 0
A10: Prix usine (aile + bags + goodies) | B10: 838
A11: Coûts logistiques | B11: 45
A12: Taxes import (2.7%) | B12: 22.63
A14: Total des couts de reviens | B14: =SUM(B10:B12) -> 905.63
A15: Frais Stripe | B15: =0.015*B6 -> 29.7
A17: MARGE BRUTE (€) | B17: =B7-B10-B11-B12-B15 -> 714.67
A18: MARGE BRUTE (%) | B18: =1/B7*B17 -> 0.43313333
A20: 2. VENTE B2C2B (Site internet avec partenaires)
A21: Marge partenaire : 20% du prix HT
A22: Modèle | B22: A+ Classic | C22: B- Ultra | D22: K2- Ultra
A23: Prix de vente TTC | B23: 3200 | C23: 4200 | D23: 2800
A24: Prix de vente HT | B24: 2666.67 | C24: 3500 | D24: 2333.33
A28: Prix usine ( aile+sac+goodies) | B28: 838 | C28: 1099 | D28: 680
A29: Coûts logistiques | B29: 45 | C29: 45 | D29: 45
A30: Taxes import (2.7%) | B30: 22.63 | C30: 29.67 | D30: 18.36
A32: Total des couts de reviens | B32: =SUM(B28:B30) -> 905.63 | C32: =SUM(C28:C30) -> 1173.67 | D32: =SUM(D28:D30) -> 743.36
A33: Frais payment | B33: =0.015*B23 -> 48 | C33: =0.015*C23 -> 63 | D33: =0.015*D23 -> 42
A34: Marge Partenaire (20%) | B34: =B24*0.2 -> 533.334 | C34: =C24*0.2 -> 700 | D34: =D24*0.2 -> 466.666
A35: MARGE BRUTE (€) | B35: =B24-B34-B28-B29-B30-B33 -> 1179.706 | C35: =C24-C34-C28-C29-C30-C33 -> 1563.33 | D35: =D24-D34-D28-D29-D30-D33 -> 1081.304
A36: MARGE BRUTE (%) | B36: =1/B24*B35 -> 0.4423892 | C36: =1/C24*C35 -> 0.44666571 | D36: =1/D24*D35 -> 0.46341666
A38: 3. Hypothèse 1 de la répartition des ventes
A39: Canal de vente | B39: Produit | C39: Prix HT | D39: Marge € | E39: Cout de reviens | F39: Proportions des ventes | G39: Marge Brute
A40: School Pack | B40: A+ Classic | C40: =B7 -> 1650 | D40: =B17 -> 714.67 | E40: =B14 -> 905.63 | F40: 0.3 | G40: =B18 -> 0.43313333
A41: B2C2B | B41: A+ Classic | C41: =B24 -> 2666.67 | D41: =B35 -> 1179.706 | E41: =B32 -> 905.63 | F41: 0.2 | G41: =B36 -> 0.4423892
A42: B2C2B | B42: B- Ultra | C42: =C24 -> 3500 | D42: =C35 -> 1563.33 | E42: =C32 -> 1173.67 | F42: 0.25 | G42: =C36 -> 0.44666571
A43: B2C2B | B43: K2- Ultra | C43: =D24 -> 2333.33 | D43: =D35 -> 1081.304 | E43: =D32 -> 743.36 | F43: 0.25 | G43: =D36 -> 0.46341666
A45: Hypothese 1: prix moyenne / produit | C45: =(C40*F40)+(C41*F41)+(C42*F42)+(C43*F43) -> 2486.6665 | D45: =(D40*F40)+(D41*F41)+(D42*F42)+(D43*F43) -> 1111.5007 | E45: =(E40*F40)+(E41*F41)+(E42*F42)+(E43*F43) -> 932.0725 | G45: =(G40*F40)+(G41*F41)+(G42*F42)+(G43*F43) -> 0.44593843

Sheet Financement
A1: FINANCEMENT & MONTAGE SOCIÉTÉ - PLUME PARAGLIDERS
A3: MONTAGE SOCIÉTÉ - CAPITAL SOCIAL
A4: Associé / Source | B4: Apport total | C4: Capital social | D4: Part capital
A5: Jean-Baptiste Chandelier | B5: 104000 | C5: 55000 | D5: 0.55
A6: Thomas Pierre-Bes | B6: 85000 | C6: 45000 | D6: 0.45
A7: Sous-total Associés | B7: =SUM(B5:B6) -> 189000 | C7: =SUM(C5:C6) -> 100000 | D7: =SUM(D5:D6) -> 1
A9: FINANCEMENTS EXTERNES
A10: Source | B10: Montant | C10: Type | D10: Année
A11: Banque Populaire - Emprunt 1/1 | B11: 189000 | C11: Emprunt 4 ans | D11: 2026
A13: Sous-total Financements Externes | B13: 189000
A15: APPORT COMPLÉMENTAIRE ANNÉE 2
A16: Source | B16: Montant | C16: Objet | D16: Année
A17: Avoir EURL JB Chandelier | B17: 50000 | C17: Marketing & Tests | D17: 2027
A18: Note: Prestation externe pour fonds de roulement
A20: RÉCAPITULATIF FINANCEMENT TOTAL
A21: Apports associés (Année 1) | B21: =B7 -> 189000
A22: Financements externes (Année 1) | B22: =B13 -> 189000
A23: Avoir EURL JB Chandelier (Année 2) | B23: =B17 -> 50000
A24: TOTAL FINANCEMENT | B24: 428000
A26: FLUX DE FINANCEMENT PAR ANNÉE
A27: Année | B27: Entrées | C27: Détail
A28: 2025 | B28: 378000 | C28: Associés + Emprunt
A29: 2026 | B29: 0 | C29: -
A30: 2027 | B30: 50000 | C30: Avoir EURL JB Chandelier
A31: 2028+ | B31: 0 | C31: -
A33: CAPITAL SOCIAL DE LA SOCIÉTÉ
A34: Capital social total | B34: =C7 -> 100000
A35: Répartition: JB Chandelier 55% / Thomas Pierre-Bes 45%
A36: Note: La différence entre apports totaux (189k€) et capital social (100k€)
A37: correspond aux comptes courants d'associés (89k€).
A40: 📅 CALENDRIER DE DÉBLOCAGE (Création 15/12/2025)
A41: 15/12/2025 | B41: Capital social | C41: 100000
A42: Janvier 2026 | B42: Comptes courants associés | C42: 89000
A43: Mars 2026 | B43: Emprunt Banque Populaire | C43: 189000
A46: Janvier 2027 | B46: Avoir EURL JB | C46: 50000
A49: ━━━━━━━━━━━━━━━━━━━━━━━━━━━━━━━━━━━━━━━━━━━━━━━━━━━━━━━━━━━━━━
A50: 💼 FINANCEMENT COMPLÉMENTAIRE - 30 000 €
A52: PRÉSENTATION COMPTABLE RETENUE :
A54: Dans le bilan prévisionnel, ce montant est présenté comme :
A55: → APPORT EN COMPTE COURANT D'ASSOCIÉ (dirigeant)
...

Sheet Scénarios
A1: SCÉNARIOS DE VENTES - PLUME PARAGLIDERS
A3: ='Marges Produits'!A38 -> 3. Hypothèse 1 de la répartition des ventes
A4: {='Marges Produits'!A39:F39} -> Canal de vente | B4: Produit | C4: Prix HT | D4: Marge € | E4: Cout de reviens | F4: Proportions des ventes
A5: {='Marges Produits'!A40:F40} -> School Pack | B5: A+ Classic | C5: 1650 | D5: 714.67 | E5: 905.63 | F5: 0.3
A6: {='Marges Produits'!A41:F41} -> B2C2B | B6: A+ Classic | C6: 2666.67 | D6: 1179.706 | E6: 905.63 | F6: 0.2
A7: {='Marges Produits'!A42:F42} -> B2C2B | B7: B- Ultra | C7: 3500 | D7: 1563.33 | E7: 1173.67 | F7: 0.25
A8: {='Marges Produits'!A43:F43} -> B2C2B | B8: K2- Ultra | C8: 2333.33 | D8: 1081.304 | E8: 743.36 | F8: 0.25
A10: {='Marges Produits'!A45:E45} -> Hypothese 1: prix moyenne / produit | B10: 0 | C10: 2486.6665 | D10: 1111.5007 | E10: 932.0725
A13: VOLUMES DE VENTES (Nombre d'ailes)
A14: Année | B14: 2025 | C14: 2026 | D14: 2027 | E14: 2028 | F14: 2029 | G14: 2030 | H14: 2031
A16: 🟠 RÉALISTE | B16: 0 | C16: 75 | D16: 250 | E16: 550 | F16: 800 | G16: 1000 | H16: 1000
A17: 🔴 POINT MORT (minimum syndical) | B17: ='Analyse Point Mort'!B19 -> 0 | C17: ='Analyse Point Mort'!C19 -> 0 | D17: ='Analyse Point Mort'!D19 -> 120 | E17: ='Analyse Point Mort'!E19 -> 300 | F17: ='Analyse Point Mort'!F19 -> 180 | G17: ='Analyse Point Mort'!G19 -> 190 | H17: ='Analyse Point Mort'!H19 -> 150
A19: SCÉNARIO RÉALISTE - DÉTAIL
A20: Volume TOTAL | B20: =B16 -> 0 | C20: =C16 -> 75 | D20: =D16 -> 250 | E20: =E16 -> 550 | F20: =F16 -> 800 | G20: =G16 -> 1000 | H20: =H16 -> 1000
A21: résultat net | B21: ='Compte de Résultat'!B34 -> -22657.971 | C21: ='Compte de Résultat'!C34 -> -122170.51 | D21: ='Compte de Résultat'!D34 -> 70886.784 | E21: ='Compte de Résultat'!E34 -> 400488.99 | F21: ='Compte de Résultat'!F34 -> 675607.84 | G21: ='Compte de Résultat'!G34 -> 895848.81 | H21: ='Compte de Résultat'!H34 -> 950429.18
A22: CA TOTAL (HT) | B22: =Dashboard!C22 -> 0 | C22: =Dashboard!D22 -> 186499.99 | D22: =Dashboard!E22 -> 621666.63 | E22: =Dashboard!F22 -> 1367666.6 | F22: =Dashboard!G22 -> 1989333.2 | G22: =Dashboard!H22 -> 2486666.5 | H22: =Dashboard!I22 -> 2610999.8
A29: COMPARAISON CA TOTAL (HT)
A31: 🟠 CA Réaliste | B31: =B22 -> 0 | C31: =C22 -> 186499.99 | D31: =D22 -> 621666.63 | E31: =E22 -> 1367666.6 | F31: =F22 -> 1989333.2 | G31: =G22 -> 2486666.5 | H31: =H22 -> 2610999.8
A34: 📌 STRATÉGIE PLAFOND 1000 AILES
A35: Au-delà de 1000 ailes/an, l'objectif n'est plus d'augmenter le volume mais la marge.
A36: Stratégie : produire légèrement moins que la demande pour valoriser le produit et augmenter le prix.
A37: Cette limitation volontaire de la production permet de renforcer le positionnement premium.

Sheet Plan Trésorerie Mensuel
A1: PLAN DE TRÉSORERIE MENSUEL - PLUME PARAGLIDERS
A2: Création : 15 décembre 2025 • Délais de financement réalistes
A4: 📅 ANNÉE 2026 : LANCEMENT
B5: Déc 25 | C5: Jan | D5: Fév | E5: Mar | F5: Avr | G5: Mai | H5: Juin | I5: Juil | J5: Août | K5: Sept | L5: Oct | M5: Nov | N5: Déc | O5: TOTAL
A6: ENTRÉES
A7: Capital social | B7: =Dashboard!B9 -> 100000 | C7: 0 | D7: 0 | E7: 0 | F7: 0 | G7: 0 | H7: 0 | I7: 0 | J7: 0 | K7: 0 | L7: 0 | M7: 0 | N7: 0 | O7: =SUM(B7:N7) -> 100000
A8: Comptes courants associés | B8: 0 | C8: 89000 | D8: 0 | E8: 0 | F8: 0 | G8: 0 | H8: 0 | I8: 0 | J8: 0 | K8: 0 | L8: 0 | M8: 0 | N8: 0 | O8: =SUM(B8:N8) -> 89000
A9: Emprunt bancaire | B9: 0 | C9: 0 | D9: 0 | E9: =Dashboard!L9 -> 189000 | F9: 0 | G9: 0 | H9: 0 | I9: 0 | J9: 0 | K9: 0 | L9: 0 | M9: 0 | N9: 0 | O9: =SUM(B9:N9) -> 189000
A12: CA Ventes (HT) | B12: 0 | C12: =C33*'Marges Produits'!$C$45 -> 0 | D12: =D33*'Marges Produits'!$C$45 -> 0 | E12: =E33*'Marges Produits'!$C$45 -> 0 | F12: =F33*'Marges Produits'!$C$45 -> 12433.333 | G12: =G33*'Marges Produits'!$C$45 -> 17406.666 | H12: =H33*'Marges Produits'!$C$45 -> 22379.999 | I12: =I33*'Marges Produits'!$C$45 -> 29839.998 | J12: =J33*'Marges Produits'!$C$45 -> 29839.998 | ... N12: =N33*'Marges Produits'!$C$45 -> 12433.333 | O12: =SUM(B12:N12) -> 186499.99
A13: Total entrées | B13: =SUM(B7:B12) -> 100000 | C13: =SUM(C7:C12) -> 89000 | D13: =SUM(D7:D12) -> 0 | E13: =SUM(E7:E12) -> 189000 | F13: =SUM(F7:F12) -> 12433.333 | G13: =SUM(G7:G12) -> 17406.666 | H13: =SUM(H7:H12) -> 22379.999 | I13: =SUM(I7:I12) -> 29839.998 | ... N13: =SUM(N7:N12) -> 12433.333 | O13: =SUM(B13:N13) -> 564499.99
A15: SORTIES
A16: Frais création | B16: ='Frais de lancement'!B9 -> 3803 | C16: 0 | D16: 0 | E16: 0 | F16: 0 | G16: 0 | H16: 0 | I16: 0 | J16: 0 | K16: 0 | L16: 0 | M16: 0 | N16: 0 | O16: =SUM(B16:N16) -> 3803
A17: Frais prototype | B17: 10000 | C17: 0 | D17: 0 | E17: 0 | F17: 0 | G17: 0 | H17: 10000 | I17: 0 | J17: 0 | K17: 6000 | L17: 0 | M17: 0 | N17: 0 | O17: =SUM(B17:N17) -> 26000
A18: Masse salariale | B18: =C18/2 -> 4228.1667 | C18: ='Charges Fixes Plume'!D13/12 -> 8456.3333 | D18: 8316 | E18: 8316 | F18: 8316 | G18: 8316 | H18: 8316 | I18: 8316 | J18: 8316 | K18: 8316 | L18: 8316 | M18: 8316 | N18: 8316 | O18: =SUM(B18:N18) -> 104160.5
A19: Charges exploitation | B19: =C19/2 -> 1671.4167 | C19: ='Charges Fixes Plume'!$C$28/12 -> 3342.8333 | D19: ='Charges Fixes Plume'!$C$28/12 -> 3342.8333 | E19: ='Charges Fixes Plume'!$C$28/12 -> 3342.8333 | F19: ='Charges Fixes Plume'!$C$28/12 -> 3342.8333 | G19: ='Charges Fixes Plume'!$C$28/12 -> 3342.8333 | H19: ='Charges Fixes Plume'!$C$28/12 -> 3342.8333 | I19: ='Charges Fixes Plume'!$C$28/12 -> 3342.8333 | J19: ='Charges Fixes Plume'!$C$28/12 -> 3342.8333 | ... N19: ='Charges Fixes Plume'!$C$28/12 -> 3342.8333 | O19: =SUM(B19:N19) -> 41785.417
A20: Pré-série homologation (10) | B20: 0 | C20: 0 | D20: 0 | E20: ='Charges Fixes Plume'!C35*4 -> 4473.948 | F20: ='Charges Fixes Plume'!C35*4 -> 4473.948 | G20: 0 | H20: 0 | I20: 0 | J20: =4*'Charges Fixes Plume'!$C$35 -> 4473.948 | K20: 0 | L20: 0 | M20: 0 | N20: 0 | O20: =SUM(B20:N20) -> 13421.844
A21: Tests homologation EN | B21: 0 | C21: 0 | D21: 0 | E21: ='Charges Fixes Plume'!C36 -> 5570 | F21: ='Charges Fixes Plume'!C36 -> 5570 | G21: 0 | H21: 0 | I21: 0 | J21: 1000 | K21: 0 | L21: 0 | M21: 0 | N21: 0 | O21: =SUM(B21:N21) -> 12140
A22: Production | B22: 0 | C22: =C32*'Marges Produits'!$E$45 -> 0 | D22: =D32*'Marges Produits'!$E$45 -> 0 | E22: =E32*'Marges Produits'!$E$45 -> 9320.725 | F22: =F32*'Marges Produits'!$E$45 -> 18641.45 | G22: =G32*'Marges Produits'!$E$45 -> 18641.45 | H22: =H32*'Marges Produits'!$E$45 -> 8388.6525 | I22: =I32*'Marges Produits'!$E$45 -> 11184.87 | J22: =J32*'Marges Produits'!$E$45 -> 9320.725 | ... N22: =N32*'Marges Produits'!$E$45 -> 4660.3625 | O22: =SUM(B22:N22) -> 103460.05
A23: Remboursement emprunt | B23: 0 | C23: 0 | D23: 0 | E23: 0 | F23: ='Emprunt Bancaire'!$B$27 -> 4367 | G23: ='Emprunt Bancaire'!$B$27 -> 4367 | H23: ='Emprunt Bancaire'!$B$27 -> 4367 | I23: ='Emprunt Bancaire'!$B$27 -> 4367 | J23: ='Emprunt Bancaire'!$B$27 -> 4367 | K23: ='Emprunt Bancaire'!$B$27 -> 4367 | L23: ='Emprunt Bancaire'!$B$27 -> 4367 | M23: ='Emprunt Bancaire'!$B$27 -> 4367 | N23: ='Emprunt Bancaire'!$B$27 -> 4367 | O23: =SUM(B23:N23) -> 39303
A24: Assurance RC (0.8% CA) | B24: =B12*0.008 -> 0 | C24: =C12*0.008 -> 0 | D24: =D12*0.008 -> 0 | E24: =E12*0.008 -> 0 | F24: =F12*0.008 -> 99.46666 | G24: =G12*0.008 -> 139.25332 | H24: =H12*0.008 -> 179.03999 | I24: =I12*0.008 -> 238.71998 | ... N24: =N12*0.008 -> 99.46666 | O24: =SUM(B24:N24) -> 1491.9999
A25: imprévue: 15% de total sortie | B25: {=SUM(B16:B24*0.15)} -> 2955.3875 | C25: {=SUM(C16:C24*0.15)} -> 1769.875 | D25: {=SUM(D16:D24*0.15)} -> 1748.825 | E25: {=SUM(E16:E24*0.15)} -> 4653.526 | F25: {=SUM(F16:F24*0.15)} -> 6721.6047 | G25: {=SUM(G16:G24*0.15)} -> 5220.9805 | H25: {=SUM(H16:H24*0.15)} -> 5189.0289 | I25: {=SUM(I16:I24*0.15)} -> 4117.4135 | ... N25: {=SUM(N16:N24*0.15)} -> 3117.8494 | O25: =SUM(B25:N25) -> 51834.871
A26: Total sorties | B26: =SUM(B16:B25) -> 22657.971 | C26: =SUM(C16:C25) -> 13569.042 | D26: =SUM(D16:D25) -> 13407.658 | E26: =SUM(E16:E25) -> 35677.032 | F26: =SUM(F16:F25) -> 51532.303 | G26: =SUM(G16:G25) -> 40027.517 | H26: =SUM(H16:H25) -> 39782.555 | I26: =SUM(I16:I25) -> 31566.837 | ... N26: =SUM(N16:N25) -> 23903.512 | O26: =SUM(B26:N26) -> 397400.68
A28: FLUX MENSUEL | B28: =B13-B26 -> 77342.029 | C28: =C13-C26 -> 75430.958 | D28: =D13-D26 -> -13407.658 | E28: =E13-E26 -> 153322.97 | F28: =F13-F26 -> -39098.97 | G28: =G13-G26 -> -22620.852 | H28: =H13-H26 -> -17402.556 | I28: =I13-I26 -> -1726.8388 | ... N28: =N13-N26 -> -11470.179 | O28: =SUM(C28:N28) -> 89757.279
A29: TRÉSORERIE CUMULÉE | B29: =B28 -> 77342.029 | C29: =B29+C28 -> 152772.99 | D29: =C29+D28 -> 139365.33 | E29: =D29+E28 -> 292688.3 | F29: =E29+F28 -> 253589.33 | G29: =F29+G28 -> 230968.48 | H29: =G29+H28 -> 213565.92 | I29: =H29+I28 -> 211839.08 | J29: =I29+J28 -> 205960.97 | ... N29: =M29+N28 -> 167099.31
A31: 📦 Volumes
A32: Production (nb ailes) | B32: 0 | C32: 0 | D32: 0 | E32: 10 | F32: 20 | G32: 20 | H32: 9 | I32: 12 | J32: 10 | K32: 10 | L32: 10 | M32: 5 | N32: 5 | O32: =SUM(B32:N32) -> 111
A33: Ventes (nb ailes) | B33: 0 | C33: 0 | D33: 0 | E33: 0 | F33: 5 | G33: 7 | H33: 9 | I33: 12 | J33: 12 | K33: 10 | L33: 10 | M33: 5 | N33: 5 | O33: =SUM(B33:N33) -> 75
A34: Stock fin de mois | B34: 0 | C34: =(C32+B34)-C33 -> 0 | D34: =(D32+C34)-D33 -> 0 | E34: =(E32+D34)-E33 -> 10 | F34: =(F32+E34)-F33 -> 25 | G34: =(G32+F34)-G33 -> 38 | H34: =(H32+G34)-H33 -> 38 | I34: =(I32+H34)-I33 -> 38 | J34: =(J32+I34)-J33 -> 36 | ... N34: =(N32+M34)-N33 -> 36
A37: 📅 ANNÉE 2027 : CROISSANCE | B37: 📅 ANNÉE 2027 : CROISSANCE | N37: 📅 ANNÉE 2028 : CROISSANCE | Z37: 📅 ANNÉE 2029 : CROISSANCE | AL37: 📅 ANNÉE 2030 : CROISSANCE | AX37: 📅 ANNÉE 2031 : CROISSANCE
B38: Jan | C38: Fév | D38: Mar | E38: Avr | F38: Mai | G38: Juin | H38: Juil | I38: Août | J38: Sept | K38: Oct | L38: Nov | M38: Déc | N38: Jan | O38: Fév | P38: Mar | Q38: Avr | R38: Mai | S38: Juin | T38: Juil | U38: Août | V38: Sept | W38: Oct | X38: Nov | Y38: Déc | Z38: Jan | AA38: Fév | AB38: Mar | AC38: Avr | AD38: Mai | AE38: Juin | AF38: Juil | AG38: Août | AH38: Sept | AI38: Oct | AJ38: Nov | AK38: Déc | AL38: Jan | AM38: Fév | AN38: Mar | AO38: Avr | AP38: Mai | AQ38: Juin | AR38: Juil | AS38: Août | AT38: Sept | AU38: Oct | AV38: Nov | AW38: Déc | AX38: Jan | AY38: Fév | AZ38: Mar | BA38: Avr | BB38: Mai | BC38: Juin | BD38: Juil | BE38: Août | BF38: Sept | BG38: Oct | BH38: Nov | BI38: Déc
A39: ENTRÉES
A40: Avoir EURL JB | B40: 0 | C40: 0 | D40: 50000 | E40: 0 | F40: 0 | G40: 0 | H40: 0 | I40: 0 | J40: 0 | K40: 0 | L40: 0 | M40: 0
A41: CA Ventes (HT) | B41: =B61*'Marges Produits'!$C$45 -> 12433.333 | C41: =C61*'Marges Produits'!$C$45 -> 24866.665 | D41: =D61*'Marges Produits'!$C$45 -> 37299.998 | E41: =E61*'Marges Produits'!$C$45 -> 62166.663 | F41: =F61*'Marges Produits'!$C$45 -> 87033.328 | G41: =G61*'Marges Produits'!$C$45 -> 87033.328 | H41: =H61*'Marges Produits'!$C$45 -> 87033.328 | I41: =I61*'Marges Produits'!$C$45 -> 74599.995 | ... AW41: =AW61*'Marges Produits'!$C$45 -> 94493.327 | AX41: =AX61*(('Marges Produits'!$C$45)*1.05) -> 130549.99 | AY41: =AY61*(('Marges Produits'!$C$45)*1.05) -> 146215.99 | AZ41: =AZ61*(('Marges Produits'!$C$45)*1.05) -> 211490.99 | BA41: =BA61*(('Marges Produits'!$C$45)*1.05) -> 276765.98 | BB41: =BB61*(('Marges Produits'!$C$45)*1.05) -> 326374.98 | BC41: =BC61*(('Marges Produits'!$C$45)*1.05) -> 326374.98 | BD41: =BD61*(('Marges Produits'!$C$45)*1.05) -> 326374.98 | BE41: =BE61*(('Marges Produits'!$C$45)*1.05) -> 276765.98 | ... BI41: =BI61*(('Marges Produits'!$C$45)*1.05) -> 99217.993
A42: Total entrées | B42: =SUM(B40:B41) -> 12433.333 | C42: =SUM(C40:C41) -> 24866.665 | D42: =SUM(D40:D41) -> 87299.997 | E42: =SUM(E40:E41) -> 62166.663 | F42: =SUM(F40:F41) -> 87033.328 | G42: =SUM(G40:G41) -> 87033.328 | H42: =SUM(H40:H41) -> 87033.328 | I42: =SUM(I40:I41) -> 74599.995 | ... BI42: =SUM(BI40:BI41) -> 99217.993
A44: SORTIES
A45: Frais prototype | B45: ='Charges Fixes Plume'!$C$33*2 -> 2236.974 | C45: ='Charges Fixes Plume'!$C$33*2 -> 2236.974 | D45: ='Charges Fixes Plume'!$C$33*2 -> 2236.974 | E45: ='Charges Fixes Plume'!$C$33*2 -> 2236.974 | F45: ='Charges Fixes Plume'!$C$33*2 -> 2236.974 | G45: ='Charges Fixes Plume'!$C$33*2 -> 2236.974 | H45: ='Charges Fixes Plume'!$C$33*2 -> 2236.974 | I45: ='Charges Fixes Plume'!$C$33*2 -> 2236.974 | ... BI45: ='Charges Fixes Plume'!$C$33*2 -> 2236.974
A46: Masse salariale | B46: ='Charges Fixes Plume'!$D$13/12 -> 8456.3333 | C46: ='Charges Fixes Plume'!$D$13/12 -> 8456.3333 | D46: ='Charges Fixes Plume'!$D$13/12 -> 8456.3333 | E46: ='Charges Fixes Plume'!$D$13/12 -> 8456.3333 | F46: ='Charges Fixes Plume'!$D$13/12 -> 8456.3333 | G46: ='Charges Fixes Plume'!$D$13/12 -> 8456.3333 | H46: ='Charges Fixes Plume'!$D$13/12 -> 8456.3333 | I46: ='Charges Fixes Plume'!$D$13/12 -> 8456.3333 | ... BI46: ='Charges Fixes Plume'!$D$13/12 -> 8456.3333
A47: Charges exploitation | B47: ='Charges Fixes Plume'!$C$28/12 -> 3342.8333 | C47: ='Charges Fixes Plume'!$C$28/12 -> 3342.8333 | D47: ='Charges Fixes Plume'!$C$28/12 -> 3342.8333 | E47: ='Charges Fixes Plume'!$C$28/12 -> 3342.8333 | F47: ='Charges Fixes Plume'!$C$28/12 -> 3342.8333 | G47: ='Charges Fixes Plume'!$C$28/12 -> 3342.8333 | H47: ='Charges Fixes Plume'!$C$28/12 -> 3342.8333 | I47: ='Charges Fixes Plume'!$C$28/12 -> 3342.8333 | ... BI47: ='Charges Fixes Plume'!$C$28/12 -> 3342.8333
A48: Pré-série homologation (10) | B48: 0 | C48: 0 | D48: 4473.948 | E48: 4473.948 | F48: 0 | G48: 0 | H48: 0 | I48: 4473.948 | J48: 0 | K48: 0 | L48: 0 | M48: 0 | N48: 0 | O48: 0 | P48: 4473.948 | Q48: 4473.948 | R48: 0 | S48: 0 | T48: 0 | U48: 4473.948 | V48: 0 | W48: 0 | X48: 0 | Y48: 0 | Z48: 0 | AA48: 0 | AB48: 4473.948 | AC48: 4473.948 | AD48: 0 | AE48: 0 | AF48: 0 | AG48: 4473.948 | AH48: 0 | AI48: 0 | AJ48: 0 | AK48: 0 | AL48: 0 | AM48: 0 | AN48: 4473.948 | AO48: 4473.948 | AP48: 0 | AQ48: 0 | AR48: 0 | AS48: 4473.948 | AT48: 0 | AU48: 0 | AV48: 0 | AW48: 0 | AX48: 0 | AY48: 0 | AZ48: 4473.948 | BA48: 4473.948 | BB48: 0 | BC48: 0 | BD48: 0 | BE48: 4473.948 | BF48: 0 | BG48: 0 | BH48: 0 | BI48: 0
A49: Tests homologation EN | B49: 0 | C49: 0 | D49: 5570 | E49: 5570 | F49: 0 | G49: 0 | H49: 0 | I49: 1000 | J49: 0 | K49: 0 | L49: 0 | M49: 0 | N49: 0 | O49: 0 | P49: 5570 | Q49: 5570 | R49: 0 | S49: 0 | T49: 0 | U49: 1000 | V49: 0 | W49: 0 | X49: 0 | Y49: 0 | Z49: 0 | AA49: 0 | AB49: 5570 | AC49: 5570 | AD49: 0 | AE49: 0 | AF49: 0 | AG49: 1000 | AH49: 0 | AI49: 0 | AJ49: 0 | AK49: 0 | AL49: 0 | AM49: 0 | AN49: 5570 | AO49: 5570 | AP49: 0 | AQ49: 0 | AR49: 0 | AS49: 1000 | AT49: 0 | AU49: 0 | AV49: 0 | AW49: 0 | AX49: 0 | AY49: 0 | AZ49: 5570 | BA49: 5570 | BB49: 0 | BC49: 0 | BD49: 0 | BE49: 1000 | BF49: 0 | BG49: 0 | BH49: 0 | BI49: 0
...

Sheet Compte de Résultat
A1: COMPTE DE RÉSULTAT PRÉVISIONNEL - SCÉNARIO RÉALISTE
A3: PARAMÈTRES | B3: avant 1000 ailes/ans | C3: apres 1000 ailes/ans
A4: Prix moyen HT par aile | B4: ='Marges Produits'!C45 -> 2486.6665
A5: Marge brute par aile | B5: ='Marges Produits'!D45 -> 1111.5007 | C5: =B5*1.05 -> 1167.0757
A6: Coût de revient par aile | B6: ='Marges Produits'!E45 -> 932.0725
A7: Stock cible (% des ventes) | B7: 0.5
A8: Charges fixes exploitation | B8: ='Charges Fixes Plume'!D44 -> 195758.56
A10: CHIFFRE D'AFFAIRES
A11: Année | B11: 2025 | C11: 2026 | D11: 2027 | E11: 2028 | F11: 2029 | G11: 2030 | H11: 2031
A12: Volumes vendus | B12: ='Seuil Rentabilité'!B25 -> 0 | C12: ='Seuil Rentabilité'!C25 -> 75 | D12: ='Seuil Rentabilité'!D25 -> 250 | E12: ='Seuil Rentabilité'!E25 -> 550 | F12: ='Seuil Rentabilité'!F25 -> 800 | G12: ='Seuil Rentabilité'!G25 -> 1000 | H12: ='Seuil Rentabilité'!H25 -> 1000
A13: CA TOTAL HT | B13: =B12*$B$4 -> 0 | C13: =C12*$B$4 -> 186499.99 | D13: =D12*$B$4 -> 621666.63 | E13: =E12*$B$4 -> 1367666.6 | F13: =F12*$B$4 -> 1989333.2 | G13: =G12*$B$4 -> 2486666.5 | H13: ='Plan Trésorerie Mensuel'!BI65 -> 2610999.8
A15: MARGE BRUTE
A16: Marge brute totale | B16: =B12*$B$5 -> 0 | C16: =C12*$B$5 -> 83362.553 | D16: =D12*$B$5 -> 277875.17 | E16: =E12*$B$5 -> 611325.39 | F16: =F12*$B$5 -> 889200.56 | G16: =G12*$B$5 -> 1111500.7 | H16: =H12*$C$5 -> 1167075.7
A18: CHARGES FIXES
A19: Charges fixes exploitation | B19: =B21 -> 22657.971 | C19: =$B$8 -> 195758.56 | D19: =$B$8 -> 195758.56 | E19: =$B$8 -> 195758.56 | F19: =$B$8 -> 195758.56 | G19: =$B$8 -> 195758.56 | H19: =$B$8 -> 195758.56
A20: Intérêts financiers + assurance prêt (2026-2029) | B20: 0 | C20: ='Emprunt Bancaire'!D35 -> 8282.5 | D20: ='Emprunt Bancaire'!D36 -> 6256.5 | E20: ='Emprunt Bancaire'!D37 -> 4136.5 | F20: ='Emprunt Bancaire'!D38 -> 1919.5 | G20: 0 | H20: 0
A21: TOTAL CHARGES FIXES | B21: =B43-B45 -> 22657.971 | C21: =C19+C20 -> 204041.06 | D21: =D19+D20 -> 202015.06 | E21: =E19+E20 -> 199895.06 | F21: =F19+F20 -> 197678.06 | G21: =G19+G20 -> 195758.56 | H21: =H19+H20 -> 195758.56
A23: CHARGES VARIABLES
A24: Assurance (0.8% du CA) | B24: =B13*0.008 -> 0 | C24: =C13*0.008 -> 1491.9999 | D24: =D13*0.008 -> 4973.333 | E24: =E13*0.008 -> 10941.333 | F24: =F13*0.008 -> 15914.666 | G24: =G13*0.008 -> 19893.332 | H24: =H13*0.008 -> 20887.999
A25: TOTAL CHARGES VARIABLES | B25: =B24 -> 0 | C25: =C24 -> 1491.9999 | D25: =D24 -> 4973.333 | E25: =E24 -> 10941.333 | F25: =F24 -> 15914.666 | G25: =G24 -> 19893.332 | H25: =H24 -> 20887.999
A27: RÉSULTAT D'EXPLOITATION
A28: Résultat avant réinvestissement | B28: =B16-B21-B25 -> -22657.971 | C28: =C16-C21-C25 -> -122170.51 | D28: =D16-D21-D25 -> 70886.784 | E28: =E16-E21-E25 -> 400488.99 | F28: =F16-F21-F25 -> 675607.84 | G28: =G16-G21-G25 -> 895848.81 | H28: =H16-H21-H25 -> 950429.18
A33: RÉSULTAT NET
A34: RÉSULTAT NET | B34: =B28-B31 -> -22657.971 | C34: =C28-C31 -> -122170.51 | D34: =D28-D31 -> 70886.784 | E34: =E28-E31 -> 400488.99 | F34: =F28-F31 -> 675607.84 | G34: =G28-G31 -> 895848.81 | H34: =H28-H31 -> 950429.18
A36: BFR - VARIATION DE STOCK
A37: 💡 + = investir dans le stock / - = récupérer du stock
A38: Stock cible (nb ailes = 50% ventes) | B38: =B12*$B$7 -> 0 | C38: =C12*$B$7 -> 37.5 | D38: =D12*$B$7 -> 125 | E38: =E12*$B$7 -> 275 | F38: =F12*$B$7 -> 400 | G38: =G12*$B$7 -> 500 | H38: =H12*$B$7 -> 500
A39: Stock cible (€ = nb ailes × coût) | B39: =B38*$B$6 -> 0 | C39: =C38*$B$6 -> 34952.719 | D39: =D38*$B$6 -> 116509.06 | E39: =E38*$B$6 -> 256319.94 | F39: =F38*$B$6 -> 372829 | G39: =G38*$B$6 -> 466036.25 | H39: =H38*$B$6 -> 466036.25
A40: Variation stock (impact trésorerie) | B40: =B39 -> 0 | C40: =C39-B39 -> 34952.719 | D40: =D39-C39 -> 81556.344 | E40: =E39-D39 -> 139810.88 | F40: =F39-E39 -> 116509.06 | G40: =G39-F39 -> 93207.25 | H40: =H39-G39 -> 0
A42: TRÉSORERIE
A43: Apports | B43: ='Plan Trésorerie Mensuel'!B7 -> 100000 | C43: =SUM('Plan Trésorerie Mensuel'!C7:N9) -> 278000 | D43: =SUM('Plan Trésorerie Mensuel'!B40:M40) -> 50000 | E43: 0 | F43: 0 | G43: 0 | H43: 0
A44: Flux de trésorerie | B44: ='Plan Trésorerie Mensuel'!B28 -> 77342.029 | C44: ='Plan Trésorerie Mensuel'!O28 -> 89757.279 | D44: ='Plan Trésorerie Mensuel'!M66 -> 20291.25 | E44: ='Plan Trésorerie Mensuel'!Y66 -> 373928.5 | F44: ='Plan Trésorerie Mensuel'!AK66 -> 641513.7 | G44: ='Plan Trésorerie Mensuel'!AW66 -> 1002429.9 | H44: ='Plan Trésorerie Mensuel'!BI66 -> 1231735.8
A45: TRÉSORERIE CUMULÉE | B45: =B44 -> 77342.029 | C45: ='Plan Trésorerie Mensuel'!N29 -> 167099.31 | D45: =C45+D44 -> 187390.56 | E45: =D45+E44 -> 561319.06 | F45: =E45+F44 -> 1202832.8 | G45: =F45+G44 -> 2205262.6 | H45: =G45+H44 -> 3436998.4

Sheet Bilan Prévisionnel
A1: BILAN PRÉVISIONNEL - PLUME PARAGLIDERS
A2: Projection sur 7 ans (2025-2031) - Scénario Réaliste
B4: 2025 | C4: 2026 | D4: 2027 | E4: 2028 | F4: 2029 | G4: 2030 | H4: 2031
A6: ACTIF
A7: Immobilisations incorporelles (R&D capitalisée) | B7: 0 | C7: 36113 | D7: 54169 | E7: 54169 | F7: 54169 | G7: 54169 | H7: 54169
A8: Immobilisations corporelles (Matériel) | B8: 0 | C8: 3333 | D8: 5000 | E8: 5000 | F8: 5000 | G8: 5000 | H8: 5000
A9: TOTAL ACTIF IMMOBILISÉ | B9: =SUM(B7:B8) -> 0 | C9: =SUM(C7:C8) -> 39446 | D9: =SUM(D7:D8) -> 59169 | E9: =SUM(E7:E8) -> 59169 | F9: =SUM(F7:F8) -> 59169 | G9: =SUM(G7:G8) -> 59169 | H9: =SUM(H7:H8) -> 59169
A11: Stocks (ailes de démonstration) | B11: 0 | C11: ='Compte de Résultat'!C38*'Marges Produits'!$E$45 -> 34952.719 | D11: ='Compte de Résultat'!D38*'Marges Produits'!$E$45 -> 116509.06 | E11: ='Compte de Résultat'!E38*'Marges Produits'!$E$45 -> 256319.94 | F11: ='Compte de Résultat'!F38*'Marges Produits'!$E$45 -> 372829 | G11: ='Compte de Résultat'!G38*'Marges Produits'!$E$45 -> 466036.25 | H11: ='Compte de Résultat'!H38*'Marges Produits'!$E$45 -> 466036.25
A12: Créances clients | B12: 0 | C12: 0 | D12: 0 | E12: 0 | F12: 0 | G12: 0 | H12: 0
A13: Trésorerie disponible | B13: ='Plan Trésorerie Mensuel'!B28 -> 77342.029 | C13: ='Plan Trésorerie Mensuel'!N29 -> 167099.31 | D13: ='Plan Trésorerie Mensuel'!M57 -> 187390.56 | E13: ='Plan Trésorerie Mensuel'!Y57 -> 561319.06 | F13: ='Plan Trésorerie Mensuel'!AK57 -> 1202832.8 | G13: ='Plan Trésorerie Mensuel'!AW57 -> 2205262.6 | H13: ='Plan Trésorerie Mensuel'!BI57 -> 3436998.4
A14: TOTAL ACTIF CIRCULANT | B14: =SUM(B11:B13) -> 77342.029 | C14: =SUM(C11:C13) -> 202052.03 | D14: =SUM(D11:D13) -> 303899.62 | E14: =SUM(E11:E13) -> 817639 | F14: =SUM(F11:F13) -> 1575661.8 | G14: =SUM(G11:G13) -> 2671298.9 | H14: =SUM(H11:H13) -> 3903034.7
A16: TOTAL ACTIF | B16: =B9+B14 -> 77342.029 | C16: =C9+C14 -> 241498.03 | D16: =D9+D14 -> 363068.62 | E16: =E9+E14 -> 876808 | F16: =F9+F14 -> 1634830.8 | G16: =G9+G14 -> 2730467.9 | H16: =H9+H14 -> 3962203.7
A18: PASSIF
A19: Capital social | B19: 100000 | C19: 100000 | D19: 100000 | E19: 100000 | F19: 100000 | G19: 100000 | H19: 100000
A20: Comptes courants associés | B20: 0 | C20: 89000 | D20: 89000 | E20: 89000 | F20: 89000 | G20: 89000 | H20: 89000
A21: Avoir EURL JB Chandelier (compte courant) | B21: 0 | C21: 0 | D21: 50000 | E21: 50000 | F21: 50000 | G21: 50000 | H21: 50000
A22: Résultat de l'exercice | B22: ='Compte de Résultat'!B34 -> -22657.971 | C22: ='Compte de Résultat'!C34 -> -122170.51 | D22: ='Compte de Résultat'!D34 -> 70886.784 | E22: ='Compte de Résultat'!E34 -> 400488.99 | F22: ='Compte de Résultat'!F34 -> 675607.84 | G22: ='Compte de Résultat'!G34 -> 895848.81 | H22: ='Compte de Résultat'!H34 -> 950429.18
A23: Report à nouveau (résultats antérieurs) | B23: 0 | C23: =B22+C22 -> -144828.48 | D23: =C22+D22 -> -51283.721 | E23: =D22+E22 -> 471375.78 | F23: =E22+F22 -> 1076096.8 | G23: =F22+G22 -> 1571456.6 | H23: =G22+H22 -> 1846278
A24: TOTAL CAPITAUX PROPRES | B24: =B19+B25+B20+B21+B22+B23 -> 77342.029 | C24: =C19+C25+C20+C21+C22+C23 -> -77998.982 | D24: =D19+D25+D20+D21+D22+D23 -> 258603.06 | E24: =E19+E25+E20+E21+E22+E23 -> 1110864.8 | F24: =F19+F25+F20+F21+F22+F23 -> 1990704.7 | G24: =G19+G25+G20+G21+G22+G23 -> 2706305.5 | H24: =H19+H25+H20+H21+H22+H23 -> 3035707.2
A25: Apport complémentaire dirigeant * | B25: 0 | C25: 0 | D25: 0 | E25: 0 | F25: 0 | G25: 0 | H25: 0
A26: Emprunt bancaire (capital restant dû) | B26: 0 | C26: ='Emprunt Bancaire'!D51 -> 144882 | D26: ='Emprunt Bancaire'!D52 -> 98740 | E26: ='Emprunt Bancaire'!D53 -> 50478 | F26: 0 | G26: 0 | H26: 0
A27: Dettes d'exploitation | B27: =B16-B24-B26 -> 0 | C27: =C16-C24-C26 -> 174615.01 | D27: =D16-D24-D26 -> 5725.5576 | E27: =E16-E24-E26 -> -284534.77 | F27: =F16-F24-F26 -> -355873.91 | G27: =G16-G24-G26 -> 24162.431 | H27: =H16-H24-H26 -> 926496.51
A28: TOTAL DETTES | B28: =B26+B27 -> 0 | C28: =C26+C27 -> 319497.01 | D28: =D26+D27 -> 104465.56 | E28: =E26+E27 -> -234056.77 | F28: =F26+F27 -> -355873.91 | G28: =G26+G27 -> 24162.431 | H28: =H26+H27 -> 926496.51
A30: TOTAL PASSIF | B30: =B24+B28 -> 77342.029 | C30: =C24+C28 -> 241498.03 | D30: =D24+D28 -> 363068.62 | E30: =E24+E28 -> 876808 | F30: =F24+F28 -> 1634830.8 | G30: =G24+G28 -> 2730467.9 | H30: =H24+H28 -> 3962203.7
B32: 0 | C32: 0 | D32: 0 | E32: 0 | F32: 0 | G32: 0 | H32: 0
A33: ━━━━━━━━━━━━━━━━━━━━━━━━━━━━━━━━━━━━━━━━━━━━━━━━━━━━━━━━━━━━━━━━━━━━━━━━━━━━━━
A34: 📊 RATIOS FINANCIERS
A35: Année | B35: 2025 | C35: 2026 | D35: 2027 | E35: 2028 | F35: 2029 | G35: 2030 | H35: 2031
A36: Ratio d'endettement (Dettes/CP) | B36: =IF(B24=0,"-",ROUND(B28/B24,2)) -> 0 | C36: =IF(C24=0,"-",ROUND(C28/C24,2)) -> -4.1 | D36: =IF(D24=0,"-",ROUND(D28/D24,2)) -> 0.4 | E36: =IF(E24=0,"-",ROUND(E28/E24,2)) -> -0.21 | F36: =IF(F24=0,"-",ROUND(F28/F24,2)) -> -0.18 | G36: =IF(G24=0,"-",ROUND(G28/G24,2)) -> 0.01 | H36: =IF(H24=0,"-",ROUND(H28/H24,2)) -> 0.31
A37: Autonomie financière (CP/Total) | B37: =IF(B30=0,"-",ROUND(B24/B30*100,1)&"%") -> 100% | C37: =IF(C30=0,"-",ROUND(C24/C30*100,1)&"%") -> -32,3% | D37: =IF(D30=0,"-",ROUND(D24/D30*100,1)&"%") -> 71,2% | E37: =IF(E30=0,"-",ROUND(E24/E30*100,1)&"%") -> 126,7% | F37: =IF(F30=0,"-",ROUND(F24/F30*100,1)&"%") -> 121,8% | G37: =IF(G30=0,"-",ROUND(G24/G30*100,1)&"%") -> 99,1% | H37: =IF(H30=0,"-",ROUND(H24/H30*100,1)&"%") -> 76,6%
A38: Trésorerie disponible (k€) | B38: =ROUND(B13/1000,0) -> 77 | C38: =ROUND(C13/1000,0) -> 167 | D38: =ROUND(D13/1000,0) -> 187 | E38: =ROUND(E13/1000,0) -> 561 | F38: =ROUND(F13/1000,0) -> 1203 | G38: =ROUND(G13/1000,0) -> 2205 | H38: =ROUND(H13/1000,0) -> 3437
A40: ━━━━━━━━━━━━━━━━━━━━━━━━━━━━━━━━━━━━━━━━━━━━━━━━━━━━━━━━━━━━━━━━━━━━━━━━━━━━━━
A41: 📋 VENTILATION DES DETTES
A42: Année | B42: 2025 | C42: 2026 | D42: 2027 | E42: 2028 | F42: 2029 | G42: 2030 | H42: 2031
A43: Emprunt bancaire (CRD) | B43: =B26 -> 0 | C43: =C26 -> 144882 | D43: =D26 -> 98740 | E43: =E26 -> 50478 | F43: =F26 -> 0 | G43: =G26 -> 0 | H43: =H26 -> 0
A44: Dettes fournisseurs (stock) | B44: =ROUND(B11*0.05,0) -> 0 | C44: =ROUND(C11*(3/52),0) -> 2017 | D44: =ROUND(D11*(3/52),0) -> 6722 | E44: =ROUND(E11*(3/52),0) -> 14788 | F44: =ROUND(F11*(3/52),0) -> 21509 | G44: =ROUND(G11*(3/52),0) -> 26887 | H44: =ROUND(H11*(3/52),0) -> 26887
A45: Charges à payer | B45: =ROUND('Charges Fixes Plume'!D44/12,0) -> 16313 | C45: =ROUND('Charges Fixes Plume'!D44/12,0) -> 16313 | D45: =ROUND('Charges Fixes Plume'!D44/12,0) -> 16313 | E45: =ROUND('Charges Fixes Plume'!D44/12,0) -> 16313 | F45: =ROUND('Charges Fixes Plume'!D44/12,0) -> 16313 | G45: =ROUND('Charges Fixes Plume'!D44/12,0) -> 16313 | H45: =ROUND('Charges Fixes Plume'!D44/12,0) -> 16313
A46: Autres dettes (TVA, PCA, régul.) | B46: =('Compte de Résultat'!B13*0.015) -> 0 | C46: =('Compte de Résultat'!C13*0.015) -> 2797.4998 | D46: =('Compte de Résultat'!D13*0.015) -> 9324.9994 | E46: =('Compte de Résultat'!E13*0.015) -> 20514.999 | F46: =('Compte de Résultat'!F13*0.015) -> 29839.998 | G46: =('Compte de Résultat'!G13*0.015) -> 37299.998 | H46: =('Compte de Résultat'!H13*0.015) -> 39164.997
A47: TOTAL DETTES | B47: =SUM(B43:B46) -> 16313 | C47: =SUM(C43:C46) -> 166009.5 | D47: =SUM(D43:D46) -> 131100 | E47: =SUM(E43:E46) -> 102094 | F47: =SUM(F43:F46) -> 67661.998 | G47: =SUM(G43:G46) -> 80499.997 | H47: =SUM(H43:H46) -> 82364.997
A49: ━━━━━━━━━━━━━━━━━━━━━━━━━━━━━━━━━━━━━━━━━━━━━━━━━━━━━━━━━━━━━━━━━━━━━━━━━━━━━━
...

Sheet Seuil Rentabilité
A1: SEUIL DE RENTABILITÉ & BFR - PLUME PARAGLIDERS
A3: PARAMÈTRES DE BASE
A4: Prix moyen HT | B4: ='Marges Produits'!C45 -> 2486.6665
A5: Marge brute par aile | B5: ='Marges Produits'!D45 -> 1111.5007
A6: Coût de revient par aile | B6: ='Marges Produits'!E45 -> 932.0725
A7: Assurance par aile (0.8% du prix) | B7: =B4*0.008 -> 19.893332
A8: Marge nette par aile (marge - assurance) | B8: =B5-B7 -> 1091.6074
A9: Stock cible (% des ventes) | B9: 0.5
A10: Charges fixes annuelles (réf Charges Fixes D50) | B10: ='Charges Fixes Plume'!D37+'Charges Fixes Plume'!C28+'Charges Fixes Plume'!D13 -> 195758.56
A13: CALCUL PAR ANNÉE
A14: Année | B14: 2025 | C14: 2026 | D14: 2027 | E14: 2028 | F14: 2029 | G14: 2030 | H14: 2031
A15: Charges fixes exploitation | B15: 0 | C15: ='Charges Fixes Plume'!$D$44 -> 195758.56 | D15: ='Charges Fixes Plume'!$D$44 -> 195758.56 | E15: ='Charges Fixes Plume'!$D$44 -> 195758.56 | F15: ='Charges Fixes Plume'!$D$44 -> 195758.56 | G15: ='Charges Fixes Plume'!$D$44 -> 195758.56 | H15: ='Charges Fixes Plume'!$D$44 -> 195758.56
A16: Intérêts financiers (2026-2029) | B16: 0 | C16: ='Emprunt Bancaire'!B35 -> 7602 | D16: ='Emprunt Bancaire'!B36 -> 5576 | E16: ='Emprunt Bancaire'!B37 -> 3456 | F16: ='Emprunt Bancaire'!B38 -> 1239 | G16: 0 | H16: 0
A17: TOTAL CHARGES FIXES | B17: =B15+B16 -> 0 | C17: =C15+C16 -> 203360.56 | D17: =D15+D16 -> 201334.56 | E17: =E15+E16 -> 199214.56 | F17: =F15+F16 -> 196997.56 | G17: =G15+G16 -> 195758.56 | H17: =H15+H16 -> 195758.56
A19: 🔵 SEUIL DE RENTABILITÉ
A20: Seuil = Charges Fixes / Marge nette par aile
A21: SEUIL (nb ailes pour équilibre exploitation) | B21: =IF(B17=0,0,ROUNDUP(B17/$B$8,0)) -> 0 | C21: =IF(C17=0,0,ROUNDUP(C17/$B$8,0)) -> 187 | D21: =IF(D17=0,0,ROUNDUP(D17/$B$8,0)) -> 185 | E21: =IF(E17=0,0,ROUNDUP(E17/$B$8,0)) -> 183 | F21: =IF(F17=0,0,ROUNDUP(F17/$B$8,0)) -> 181 | G21: =IF(G17=0,0,ROUNDUP(G17/$B$8,0)) -> 180 | H21: =IF(H17=0,0,ROUNDUP(H17/$B$8,0)) -> 180
A23: COMPARAISON AVEC SCÉNARIOS
A24: 🔵 Seuil de rentabilité | B24: =B21 -> 0 | C24: =C21 -> 187 | D24: =D21 -> 185 | E24: =E21 -> 183 | F24: =F21 -> 181 | G24: =G21 -> 180 | H24: =H21 -> 180
A25: 🟠 Scénario Réaliste | B25: =Scénarios!B16 -> 0 | C25: =Scénarios!C16 -> 75 | D25: =Scénarios!D16 -> 250 | E25: =Scénarios!E16 -> 550 | F25: =Scénarios!F16 -> 800 | G25: =Scénarios!G16 -> 1000 | H25: =Scénarios!H16 -> 1000
A27: Écart Réaliste vs Seuil | B27: =B25-B21 -> 0 | C27: =C25-C21 -> -112 | D27: =D25-D21 -> 65 | E27: =E25-E21 -> 367 | F27: =F25-F21 -> 619 | G27: =G25-G21 -> 820 | H27: =H25-H21 -> 820
A29: BFR - GESTION DU STOCK (Scénario Réaliste)
A30: Stock = 50% des ventes. Variation = achat ou vente de stock.
A31: Stock cible (nb ailes = 50% ventes) | B31: =B25*$B$9 -> 0 | C31: =C25*$B$9 -> 37.5 | D31: =D25*$B$9 -> 125 | E31: =E25*$B$9 -> 275 | F31: =F25*$B$9 -> 400 | G31: =G25*$B$9 -> 500 | H31: =H25*$B$9 -> 500
A32: Stock cible (€ = nb ailes × coût) | B32: =B31*$B$6 -> 0 | C32: =C31*$B$6 -> 34952.719 | D32: =D31*$B$6 -> 116509.06 | E32: =E31*$B$6 -> 256319.94 | F32: =F31*$B$6 -> 372829 | G32: =G31*$B$6 -> 466036.25 | H32: =H31*$B$6 -> 466036.25
A33: Variation stock (+ = investir / - = récupérer) | B33: =B32 -> 0 | C33: =C32-B32 -> 34952.719 | D33: =D32-C32 -> 81556.344 | E33: =E32-D32 -> 139810.88 | F33: =F32-E32 -> 116509.06 | G33: =G32-F32 -> 93207.25 | H33: =H32-G32 -> 0
A35: 💡 Si ventes baissent → stock cible baisse → on revend du stock → tréso +
A36: 💡 Si ventes augmentent → stock cible augmente → on achète du stock → tréso -

Sheet Analyse Point Mort
A1: SCÉNARIO POINT MORT - MINIMUM SYNDICAL
A2: Objectif : Trésorerie cumulée ≥ 0 € (survie)
A4: PARAMÈTRES
A5: Marge nette par aile | B5: ='Seuil Rentabilité'!B8 -> 1091.6074
A6: Coût de revient par aile | B6: ='Seuil Rentabilité'!B6 -> 932.0725
A7: Stock cible (%) | B7: 0.5
A8: Charges fixes annuelles | B8: ='Charges Fixes Plume'!D44 -> 195758.56
A9: Remboursement emprunt | B9: ='Emprunt Bancaire'!D11 -> 52400
A10: Marge après BFR initial (marge - 50%×coût) | B10: =B5-B7*B6 -> 625.57112
A12: SCÉNARIO POINT MORT
A13: Année | B13: 2025 | C13: 2026 | D13: 2027 | E13: 2028 | F13: 2029 | G13: 2030 | H13: 2031
A14: Apports | B14: ='Plan Trésorerie Mensuel'!B13 -> 100000 | C14: =SUM('Plan Trésorerie Mensuel'!C8:N9) -> 278000 | D14: 50000 | E14: 0 | F14: 0 | G14: 0 | H14: 0
A15: Charges fixes (€) | B15: 10000 | C15: ='Charges Fixes Plume'!$D$44 -> 195758.56 | D15: ='Charges Fixes Plume'!$D$44 -> 195758.56 | E15: ='Charges Fixes Plume'!$D$44 -> 195758.56 | F15: ='Charges Fixes Plume'!$D$44 -> 195758.56 | G15: ='Charges Fixes Plume'!$D$44 -> 195758.56 | H15: ='Charges Fixes Plume'!$D$44 -> 195758.56
A16: Remboursement emprunt (€) | B16: 0 | C16: ='Emprunt Bancaire'!D11/12*9 -> 39300 | D16: ='Emprunt Bancaire'!$D$11 -> 52400 | E16: ='Emprunt Bancaire'!$D$11 -> 52400 | F16: ='Emprunt Bancaire'!$D$11 -> 52400 | G16: 0 | H16: 0
A17: Total sorties fixes (€) | B17: =SUM(B15:B16) -> 10000 | C17: =SUM(C15:C16) -> 235058.56 | D17: =SUM(D15:D16) -> 248158.56 | E17: =SUM(E15:E16) -> 248158.56 | F17: =SUM(F15:F16) -> 248158.56 | G17: =SUM(G15:G16) -> 195758.56 | H17: =SUM(H15:H16) -> 195758.56
A19: 🎯 VENTES MINIMUM (ailes) | B19: 0 | C19: 0 | D19: 120 | E19: 300 | F19: 180 | G19: 190 | H19: 150
A21: Marge brute générée (€) | B21: 0 | C21: 0 | D21: ='Marges Produits'!$D$45*D19 -> 133380.08 | E21: ='Marges Produits'!$D$45*E19 -> 333450.21 | F21: ='Marges Produits'!$D$45*F19 -> 200070.13 | G21: ='Marges Produits'!$D$45*G19 -> 211185.13 | H21: ='Marges Produits'!$D$45*H19 -> 166725.11
A22: Stock cible (€) | B22: 0 | C22: 0 | D22: 55924.35 | E22: 139810.88 | F22: 83886.525 | G22: 88546.887 | H22: 69905.438
A23: Variation stock (€) | B23: 0 | C23: 0 | D23: 55924.35 | E23: 83886.525 | F23: -55924.35 | G23: 4660.3625 | H23: -18641.45
A25: FLUX DE TRÉSORERIE (€) | B25: 90000 | C25: 42938 | D25: -123094.47 | E25: -4567.3146 | F25: 4250.6762 | G25: 6986.0374 | H25: -13376.445
A26: TRÉSORERIE CUMULÉE (€) | B26: 90000 | C26: 132938 | D26: 9843.5342 | E26: 5276.2196 | F26: 9526.8958 | G26: 16512.933 | H26: 3136.4884
A28: INDICATEURS
A29: Seuil rentabilité (ailes) | B29: 10 | C29: 216 | D29: 228 | E29: 228 | F29: 228 | G29: 180 | H29: 180
A30: Écart ventes vs seuil | B30: -10 | C30: -216 | D30: -108 | E30: 72 | F30: -48 | G30: 10 | H30: -30
A32: RÉSUMÉ
A33: Total ventes (7 ans) | B33: 940
A34: Moyenne annuelle (hors 2025) | B34: 156.66667
A35: Trésorerie finale | B35: 3136.4884
A36: Trésorerie minimum | B36: 3136.4884
A38: 📅 CALENDRIER DES APPORTS
A39: • Déc 2025 : Capital social = 100 000€
A40: • Jan 2026 : Comptes courants associés = 89 000€
A41: • Mar 2026 : Emprunt Banque Populaire = 189 000€
A42: • Jan 2027 : Avoir EURL JB = 50 000€
A44: 📌 MODE D'EMPLOI
A45: 1. Les cellules JAUNES (ventes) sont modifiables
A46: 2. La TRÉSORERIE CUMULÉE doit rester ≥ 0€
A47: 3. Remboursement emprunt : 9 mois en 2026, 12 mois/an 2027-2029
A49: ⚠️ Ce scénario est le STRICT MINIMUM pour survivre !

Sheet scénario-20% 
A1: PLAN DE TRÉSORERIE MENSUEL - PLUME PARAGLIDERS
A2: Création : 15 décembre 2025 • Délais de financement réalistes
A4: 📅 ANNÉE 2026 : LANCEMENT
B5: Déc 25 | C5: Jan | D5: Fév | E5: Mar | F5: Avr | G5: Mai | H5: Juin | I5: Juil | J5: Août | K5: Sept | L5: Oct | M5: Nov | N5: Déc | O5: TOTAL
A6: ENTRÉES
A7: Capital social | B7: =Dashboard!B9 -> 100000 | C7: 0 | D7: 0 | E7: 0 | F7: 0 | G7: 0 | H7: 0 | I7: 0 | J7: 0 | K7: 0 | L7: 0 | M7: 0 | N7: 0 | O7: =SUM(B7:N7) -> 100000
A8: Comptes courants associés | B8: 0 | C8: 89000 | D8: 0 | E8: 0 | F8: 0 | G8: 0 | H8: 0 | I8: 0 | J8: 0 | K8: 0 | L8: 0 | M8: 0 | N8: 0 | O8: =SUM(B8:N8) -> 89000
A9: Emprunt bancaire | B9: 0 | C9: 0 | D9: 0 | E9: =Dashboard!L9 -> 189000 | F9: 0 | G9: 0 | H9: 0 | I9: 0 | J9: 0 | K9: 0 | L9: 0 | M9: 0 | N9: 0 | O9: =SUM(B9:N9) -> 189000
A12: CA Ventes (HT) | B12: 0 | C12: =C34*'Marges Produits'!$C$45 -> 0 | D12: =D34*'Marges Produits'!$C$45 -> 0 | E12: =E34*'Marges Produits'!$C$45 -> 0 | F12: =F34*'Marges Produits'!$C$45 -> 9946.666 | G12: =G34*'Marges Produits'!$C$45 -> 12433.333 | H12: =H34*'Marges Produits'!$C$45 -> 17406.666 | I12: =I34*'Marges Produits'!$C$45 -> 22379.999 | J12: =J34*'Marges Produits'!$C$45 -> 22379.999 | ... N12: =N34*'Marges Produits'!$C$45 -> 9946.666 | O12: =SUM(B12:N12) -> 144226.66
A13: Total entrées | B13: =SUM(B7:B12) -> 100000 | C13: =SUM(C7:C12) -> 89000 | D13: =SUM(D7:D12) -> 0 | E13: =SUM(E7:E12) -> 189000 | F13: =SUM(F7:F12) -> 9946.666 | G13: =SUM(G7:G12) -> 12433.333 | H13: =SUM(H7:H12) -> 17406.666 | I13: =SUM(I7:I12) -> 22379.999 | ... N13: =SUM(N7:N12) -> 9946.666 | O13: =SUM(B13:N13) -> 522226.66
A15: SORTIES
A16: Frais création | B16: ='Frais de lancement'!B9 -> 3803 | C16: 0 | D16: 0 | E16: 0 | F16: 0 | G16: 0 | H16: 0 | I16: 0 | J16: 0 | K16: 0 | L16: 0 | M16: 0 | N16: 0 | O16: =SUM(B16:N16) -> 3803
A17: Frais prototype | B17: 10000 | C17: 0 | D17: 0 | E17: 0 | F17: 0 | G17: 0 | H17: 10000 | I17: 0 | J17: 0 | K17: 6000 | L17: 0 | M17: 0 | N17: 0 | O17: =SUM(B17:N17) -> 26000
A18: Masse salariale | B18: =C18/2 -> 4228.1667 | C18: ='Charges Fixes Plume'!D13/12 -> 8456.3333 | D18: 8316 | E18: 8316 | F18: 8316 | G18: 8316 | H18: 8316 | I18: 8316 | J18: 8316 | K18: 8316 | L18: 8316 | M18: 8316 | N18: 8316 | O18: =SUM(B18:N18) -> 104160.5
A19: Charges exploitation | B19: =C19/2 -> 1671.4167 | C19: ='Charges Fixes Plume'!C28/12 -> 3342.8333 | D19: 3018 | E19: 3018 | F19: 3018 | G19: 3018 | H19: 3018 | I19: 3018 | J19: 3018 | K19: 3018 | L19: 3018 | M19: 3018 | N19: 3018 | O19: =SUM(B19:N19) -> 38212.25
A21: Pré-série homologation (10) | B21: 0 | C21: 0 | D21: 0 | E21: ='Charges Fixes Plume'!C35*4 -> 4473.948 | F21: ='Charges Fixes Plume'!C35*4 -> 4473.948 | G21: 0 | H21: 0 | I21: 0 | J21: =4*'Charges Fixes Plume'!$C$35 -> 4473.948 | K21: 0 | L21: 0 | M21: 0 | N21: 0 | O21: =SUM(B21:N21) -> 13421.844
A22: Tests homologation EN | B22: 0 | C22: 0 | D22: 0 | E22: ='Charges Fixes Plume'!C36 -> 5570 | F22: ='Charges Fixes Plume'!C36 -> 5570 | G22: 0 | H22: 0 | I22: 0 | J22: 1000 | K22: 0 | L22: 0 | M22: 0 | N22: 0 | O22: =SUM(B22:N22) -> 12140
A23: Production | B23: 0 | C23: =C33*'Marges Produits'!$E$45 -> 0 | D23: =D33*'Marges Produits'!$E$45 -> 0 | E23: =E33*'Marges Produits'!$E$45 -> 7456.58 | F23: =F33*'Marges Produits'!$E$45 -> 14913.16 | G23: =G33*'Marges Produits'!$E$45 -> 14913.16 | H23: =H33*'Marges Produits'!$E$45 -> 6524.5075 | I23: =I33*'Marges Produits'!$E$45 -> 8388.6525 | J23: =J33*'Marges Produits'!$E$45 -> 7456.58 | ... N23: =N33*'Marges Produits'!$E$45 -> 3728.29 | O23: =SUM(B23:N23) -> 82022.38
A24: Remboursement emprunt | B24: 0 | C24: 0 | D24: 0 | E24: 0 | F24: ='Emprunt Bancaire'!$B$27 -> 4367 | G24: ='Emprunt Bancaire'!$B$27 -> 4367 | H24: ='Emprunt Bancaire'!$B$27 -> 4367 | I24: ='Emprunt Bancaire'!$B$27 -> 4367 | J24: ='Emprunt Bancaire'!$B$27 -> 4367 | K24: ='Emprunt Bancaire'!$B$27 -> 4367 | L24: ='Emprunt Bancaire'!$B$27 -> 4367 | M24: ='Emprunt Bancaire'!$B$27 -> 4367 | N24: ='Emprunt Bancaire'!$B$27 -> 4367 | O24: =SUM(B24:N24) -> 39303
A25: Assurance RC (0.8% CA) | B25: =B12*0.008 -> 0 | C25: =C12*0.008 -> 0 | D25: =D12*0.008 -> 0 | E25: =E12*0.008 -> 0 | F25: =F12*0.008 -> 79.573328 | G25: =G12*0.008 -> 99.46666 | H25: =H12*0.008 -> 139.25332 | I25: =I12*0.008 -> 179.03999 | ... N25: =N12*0.008 -> 79.573328 | O25: =SUM(B25:N25) -> 1153.8133
A26: imprévue: 15% de total sortie | B26: {=SUM(B16:B25*0.15)} -> 2955.3875 | C26: {=SUM(C16:C25*0.15)} -> 1769.875 | D26: {=SUM(D16:D25*0.15)} -> 1700.1 | E26: {=SUM(E16:E25*0.15)} -> 4325.1792 | F26: {=SUM(F16:F25*0.15)} -> 6110.6522 | G26: {=SUM(G16:G25*0.15)} -> 4607.044 | H26: {=SUM(H16:H25*0.15)} -> 4854.7141 | I26: {=SUM(I16:I25*0.15)} -> 3640.3039 | ... N26: {=SUM(N16:N25*0.15)} -> 2926.3295 | O26: =SUM(B26:N26) -> 48032.518
A27: Total sorties | B27: =SUM(B16:B26) -> 22657.971 | C27: =SUM(C16:C26) -> 13569.042 | D27: =SUM(D16:D26) -> 13034.1 | E27: =SUM(E16:E26) -> 33159.707 | F27: =SUM(F16:F26) -> 46848.334 | G27: =SUM(G16:G26) -> 35320.671 | H27: =SUM(H16:H26) -> 37219.475 | I27: =SUM(I16:I26) -> 27908.996 | ... N27: =SUM(N16:N26) -> 22435.193 | O27: =SUM(B27:N27) -> 368249.31
A29: FLUX MENSUEL | B29: =B13-B27 -> 77342.029 | C29: =C13-C27 -> 75430.958 | D29: =D13-D27 -> -13034.1 | E29: =E13-E27 -> 155840.29 | F29: =F13-F27 -> -36901.668 | G29: =G13-G27 -> -22887.338 | H29: =H13-H27 -> -19812.809 | I29: =I13-I27 -> -5528.9979 | ... N29: =N13-N27 -> -12488.527
A30: TRÉSORERIE CUMULÉE | B30: =B29 -> 77342.029 | C30: =B30+C29 -> 152772.99 | D30: =C30+D29 -> 139738.89 | E30: =D30+E29 -> 295579.18 | F30: =E30+F29 -> 258677.51 | G30: =F30+G29 -> 235790.17 | H30: =G30+H29 -> 215977.37 | I30: =H30+I29 -> 210448.37 | J30: =I30+J29 -> 199696.21 | ... N30: =M30+N29 -> 153977.35
A32: 📦 Volumes
A33: Production (nb ailes) | B33: 0 | C33: 0 | D33: 0 | E33: 8 | F33: 16 | G33: 16 | H33: 7 | I33: 9 | J33: 8 | K33: 8 | L33: 8 | M33: 4 | N33: 4 | O33: =SUM(B33:N33) -> 88
A34: Ventes (nb ailes) | B34: 0 | C34: 0 | D34: 0 | E34: 0 | F34: 4 | G34: 5 | H34: 7 | I34: 9 | J34: 9 | K34: 8 | L34: 8 | M34: 4 | N34: 4 | O34: =SUM(B34:N34) -> 58
A35: Stock fin de mois | B35: 0 | C35: =(C33+B35)-C34 -> 0 | D35: =(D33+C35)-D34 -> 0 | E35: =(E33+D35)-E34 -> 8 | F35: =(F33+E35)-F34 -> 20 | G35: =(G33+F35)-G34 -> 31 | H35: =(H33+G35)-H34 -> 31 | I35: =(I33+H35)-I34 -> 31 | J35: =(J33+I35)-J34 -> 30 | ... N35: =(N33+M35)-N34 -> 30
A38: 📅 ANNÉE 2027 : CROISSANCE | B38: 📅 ANNÉE 2027 : CROISSANCE | N38: 📅 ANNÉE 2028 : CROISSANCE | Z38: 📅 ANNÉE 2029 : CROISSANCE | AL38: 📅 ANNÉE 2030 : CROISSANCE | AX38: 📅 ANNÉE 2031 : CROISSANCE
B39: Jan | C39: Fév | D39: Mar | E39: Avr | F39: Mai | G39: Juin | H39: Juil | I39: Août | J39: Sept | K39: Oct | L39: Nov | M39: Déc | N39: Jan | O39: Fév | P39: Mar | Q39: Avr | R39: Mai | S39: Juin | T39: Juil | U39: Août | V39: Sept | W39: Oct | X39: Nov | Y39: Déc | Z39: Jan | AA39: Fév | AB39: Mar | AC39: Avr | AD39: Mai | AE39: Juin | AF39: Juil | AG39: Août | AH39: Sept | AI39: Oct | AJ39: Nov | AK39: Déc | AL39: Jan | AM39: Fév | AN39: Mar | AO39: Avr | AP39: Mai | AQ39: Juin | AR39: Juil | AS39: Août | AT39: Sept | AU39: Oct | AV39: Nov | AW39: Déc | AX39: Jan | AY39: Fév | AZ39: Mar | BA39: Avr | BB39: Mai | BC39: Juin | BD39: Juil | BE39: Août | BF39: Sept | BG39: Oct | BH39: Nov | BI39: Déc
A40: ENTRÉES
A41: Avoir EURL JB | B41: 0 | C41: 0 | D41: 50000 | E41: 0 | F41: 0 | G41: 0 | H41: 0 | I41: 0 | J41: 0 | K41: 0 | L41: 0 | M41: 0
A42: CA Ventes (HT) | B42: =B63*'Marges Produits'!$C$45 -> 9946.666 | C42: =C63*'Marges Produits'!$C$45 -> 19893.332 | D42: =D63*'Marges Produits'!$C$45 -> 29839.998 | E42: =E63*'Marges Produits'!$C$45 -> 49733.33 | F42: =F63*'Marges Produits'!$C$45 -> 69626.662 | G42: =G63*'Marges Produits'!$C$45 -> 69626.662 | H42: =H63*'Marges Produits'!$C$45 -> 69626.662 | I42: =I63*'Marges Produits'!$C$45 -> 59679.996 | ... AW42: =AW63*'Marges Produits'!$C$45 -> 74599.995 | AX42: =AX63*(('Marges Produits'!$C$45)*1.05) -> 104439.99 | AY42: =AY63*(('Marges Produits'!$C$45)*1.05) -> 114883.99 | AZ42: =AZ63*(('Marges Produits'!$C$45)*1.05) -> 167103.99 | BA42: =BA63*(('Marges Produits'!$C$45)*1.05) -> 219323.99 | BB42: =BB63*(('Marges Produits'!$C$45)*1.05) -> 261099.98 | BC42: =BC63*(('Marges Produits'!$C$45)*1.05) -> 261099.98 | BD42: =BD63*(('Marges Produits'!$C$45)*1.05) -> 261099.98 | BE42: =BE63*(('Marges Produits'!$C$45)*1.05) -> 219323.99 | ... BI42: =BI63*(('Marges Produits'!$C$45)*1.05) -> 78329.995
A43: Total entrées | B43: =SUM(B41:B42) -> 9946.666 | C43: =SUM(C41:C42) -> 19893.332 | D43: =SUM(D41:D42) -> 79839.998 | E43: =SUM(E41:E42) -> 49733.33 | F43: =SUM(F41:F42) -> 69626.662 | G43: =SUM(G41:G42) -> 69626.662 | H43: =SUM(H41:H42) -> 69626.662 | I43: =SUM(I41:I42) -> 59679.996 | ... BI43: =SUM(BI41:BI42) -> 78329.995
A45: SORTIES
A46: Frais prototype | B46: ='Charges Fixes Plume'!$C$33*2 -> 2236.974 | C46: ='Charges Fixes Plume'!$C$33*2 -> 2236.974 | D46: ='Charges Fixes Plume'!$C$33*2 -> 2236.974 | E46: ='Charges Fixes Plume'!$C$33*2 -> 2236.974 | F46: ='Charges Fixes Plume'!$C$33*2 -> 2236.974 | G46: ='Charges Fixes Plume'!$C$33*2 -> 2236.974 | H46: ='Charges Fixes Plume'!$C$33*2 -> 2236.974 | I46: ='Charges Fixes Plume'!$C$33*2 -> 2236.974 | ... BI46: ='Charges Fixes Plume'!$C$33*2 -> 2236.974
A47: Masse salariale | B47: ='Charges Fixes Plume'!$D$13/12 -> 8456.3333 | C47: ='Charges Fixes Plume'!$D$13/12 -> 8456.3333 | D47: ='Charges Fixes Plume'!$D$13/12 -> 8456.3333 | E47: ='Charges Fixes Plume'!$D$13/12 -> 8456.3333 | F47: ='Charges Fixes Plume'!$D$13/12 -> 8456.3333 | G47: ='Charges Fixes Plume'!$D$13/12 -> 8456.3333 | H47: ='Charges Fixes Plume'!$D$13/12 -> 8456.3333 | I47: ='Charges Fixes Plume'!$D$13/12 -> 8456.3333 | ... BI47: ='Charges Fixes Plume'!$D$13/12 -> 8456.3333
A48: Charges exploitation | B48: ='Charges Fixes Plume'!$C$28/12 -> 3342.8333 | C48: ='Charges Fixes Plume'!$C$28/12 -> 3342.8333 | D48: ='Charges Fixes Plume'!$C$28/12 -> 3342.8333 | E48: ='Charges Fixes Plume'!$C$28/12 -> 3342.8333 | F48: ='Charges Fixes Plume'!$C$28/12 -> 3342.8333 | G48: ='Charges Fixes Plume'!$C$28/12 -> 3342.8333 | H48: ='Charges Fixes Plume'!$C$28/12 -> 3342.8333 | I48: ='Charges Fixes Plume'!$C$28/12 -> 3342.8333 | ... BI48: ='Charges Fixes Plume'!$C$28/12 -> 3342.8333
A49: Pré-série homologation (10) | B49: 0 | C49: 0 | D49: 4473.948 | E49: 4473.948 | F49: 0 | G49: 0 | H49: 0 | I49: 4473.948 | J49: 0 | K49: 0 | L49: 0 | M49: 0 | N49: 0 | O49: 0 | P49: 4473.948 | Q49: 4473.948 | R49: 0 | S49: 0 | T49: 0 | U49: 4473.948 | V49: 0 | W49: 0 | X49: 0 | Y49: 0 | Z49: 0 | AA49: 0 | AB49: 4473.948 | AC49: 4473.948 | AD49: 0 | AE49: 0 | AF49: 0 | AG49: 4473.948 | AH49: 0 | AI49: 0 | AJ49: 0 | AK49: 0 | AL49: 0 | AM49: 0 | AN49: 4473.948 | AO49: 4473.948 | AP49: 0 | AQ49: 0 | AR49: 0 | AS49: 4473.948 | AT49: 0 | AU49: 0 | AV49: 0 | AW49: 0 | AX49: 0 | AY49: 0 | AZ49: 4473.948 | BA49: 4473.948 | BB49: 0 | BC49: 0 | BD49: 0 | BE49: 4473.948 | BF49: 0 | BG49: 0 | BH49: 0 | BI49: 0
A50: Tests homologation EN | B50: 0 | C50: 0 | D50: 5570 | E50: 5570 | F50: 0 | G50: 0 | H50: 0 | I50: 1000 | J50: 0 | K50: 0 | L50: 0 | M50: 0 | N50: 0 | O50: 0 | P50: 5570 | Q50: 5570 | R50: 0 | S50: 0 | T50: 0 | U50: 1000 | V50: 0 | W50: 0 | X50: 0 | Y50: 0 | Z50: 0 | AA50: 0 | AB50: 5570 | AC50: 5570 | AD50: 0 | AE50: 0 | AF50: 0 | AG50: 1000 | AH50: 0 | AI50: 0 | AJ50: 0 | AK50: 0 | AL50: 0 | AM50: 0 | AN50: 5570 | AO50: 5570 | AP50: 0 | AQ50: 0 | AR50: 0 | AS50: 1000 | AT50: 0 | AU50: 0 | AV50: 0 | AW50: 0 | AX50: 0 | AY50: 0 | AZ50: 5570 | BA50: 5570 | BB50: 0 | BC50: 0 | BD50: 0 | BE50: 1000 | BF50: 0 | BG50: 0 | BH50: 0 | BI50: 0
...
